Workbook

Sheet newreqtype
A1: approute | B1: =A1 & " Interactive" -> approute Interactive | C1: lamdaname | D1: requesttype | E1: taskname | F1: statemachine | G1: parenenttype | H1: requesttype insert | I1: =H1 & " Interactive" -> requesttype insert Interactive | J1: statemachinerepot | K1: app.crontasks | L1: app.cronactions | M1: Comments
A2: 51 | B2: =A2+1 -> 52 | C2: wms-tools-lambda-in-transit-rma-asn | D2: in-transit-rma-asn-7-days | E2: In Transit RMA ASN 7 Days | F2: tbd | G2: (select rt2.requesttypeid from app.requesttype rt2 where rt2.description = 'CRON Scheduling Dashboard') | H2: ="insert into app.requesttype(requesttypeid, approute, description, longdescription) select (select max(r.requesttypeid) from app.requesttype r) + 1 requesttypeid, " & A2 & ", '" & D2 & "', '" & D2 & "' where not exists (select 1 from app.requesttype r2 where r2.approute = " & A2 & " );" -> insert into app.requesttype(requesttypeid, approute, description, longdescription) select (select max(r.requesttypeid) from app.requesttype r) + 1 requesttypeid, 51, 'in-transit-rma-asn-7-days', 'in-transit-rma-asn-7-days' where not exists (select 1 from app.requesttype r2 where r2.approute = 51 ); | I2: ="insert into app.requesttype(requesttypeid, approute, description, longdescription) select (select max(r.requesttypeid) from app.requesttype r) + 1 requesttypeid, " & B2 & ", '" & D2 & " Interactive', '" & D2 & " Interactive' where not exists (select 1 from app.requesttype r2 where r2.approute = " & B2 & " );" -> insert into app.requesttype(requesttypeid, approute, description, longdescription) select (select max(r.requesttypeid) from app.requesttype r) + 1 requesttypeid, 52, 'in-transit-rma-asn-7-days Interactive', 'in-transit-rma-asn-7-days Interactive' where not exists (select 1 from app.requesttype r2 where r2.approute = 52 ); | J2: ="insert into app.statemachinerepo(statemachine, description, requesttypeid) select '" & F2 & "-' || rt.description" & ", '" & F2 & "-' || rt.description" & ", rt.requesttypeid from app.requesttype rt where rt.description = '" & D2 & "' and not exists (select 1 from app.statemachinerepo sr where sr.description = '" & F2 & "-" & D2 & "');" -> insert into app.statemachinerepo(statemachine, description, requesttypeid) select 'tbd-' || rt.description, 'tbd-' || rt.description, rt.requesttypeid from app.requesttype rt where rt.description = 'in-transit-rma-asn-7-days' and not exists (select 1 from app.statemachinerepo sr where sr.description = 'tbd-in-transit-rma-asn-7-days'); | K2: {="insert into app.cronaction (CronTaskId, CronActionTypeId, Payload, CreatedBy, LastUpdatedBy) select c.crontaskid, cat.CronActionTypeId,'{""EmailTextOnError"":""tbd"",""TaskName"":""" & E2 & """, ""StateMachine"":""" & IF(ISNUMBER(SEARCH("DB Alert", E)), "wms-tools-state-machine-db-alert", """ wms-tools-state-machine-" & D2 & "" ) & """, "" Lambda "":"" & C2 & "", ""RequestType"":""" & D2 &"""}','sysuser', 'sysuser' from app.cronactiontype cat, app.crontasks c where c.description = '" & E2 & "' and not exists (select 1 from app.cronaction c2 where c2.crontaskid = c.crontaskid) and cat.description = 'NONE';"} -> insert into app.cronaction (CronTaskId, CronActionTypeId, Payload, CreatedBy, LastUpdatedBy) select c.crontaskid, cat.CronActionTypeId,'{"EmailTextOnError":"tbd","TaskName":"In Transit RMA ASN 7 Days", "StateMachine":"" wms-tools-state-machine-in-transit-rma-asn-7-days", " Lambda ":" & C2 & ", "RequestType":"in-transit-rma-asn-7-days"}','sysuser', 'sysuser' from app.cronactiontype cat, app.crontasks c where c.description = 'In Transit RMA ASN 7 Days' and not exists (select 1 from app.cronaction c2 where c2.crontaskid = c.crontaskid) and cat.description = 'NONE'; | L2: ="insert into app.cronaction (CronTaskId, CronActionTypeId, Payload, CreatedBy, LastUpdatedBy) select c.crontaskid, cat.CronActionTypeId,'{""EmailTextOnError"":""tbd"",""TaskName"":""" & E2 & """, ""StateMachine"":""" & IF(ISNUMBER(SEARCH("DB Alert", E2)), "wms-tools-state-machine-db-alert", """ wms-tools-state-machine-" & D2 & "" ) & """, "" Lambda "":""" & C2 & """, ""RequestType"":""" & D2 &"""}','sysuser', 'sysuser' from app.cronactiontype cat, app.crontasks c where c.description = '" & E2 & "' and not exists (select 1 from app.cronaction c2 where c2.crontaskid = c.crontaskid) and cat.description = 'NONE';" -> insert into app.cronaction (CronTaskId, CronActionTypeId, Payload, CreatedBy, LastUpdatedBy) select c.crontaskid, cat.CronActionTypeId,'{"EmailTextOnError":"tbd","TaskName":"In Transit RMA ASN 7 Days", "StateMachine":"" wms-tools-state-machine-in-transit-rma-asn-7-days", " Lambda ":"wms-tools-lambda-in-transit-rma-asn", "RequestType":"in-transit-rma-asn-7-days"}','sysuser', 'sysuser' from app.cronactiontype cat, app.crontasks c where c.description = 'In Transit RMA ASN 7 Days' and not exists (select 1 from app.cronaction c2 where c2.crontaskid = c.crontaskid) and cat.description = 'NONE';
A3: 53 | B3: =A3+1 -> 54 | C3: wms-tools-lambda-in-transit-rma-asn | D3: in-transit-rma-asn-30-days | E3: In Transit RMA ASN 30 Days | F3: tbd | G3: (select rt2.requesttypeid from app.requesttype rt2 where rt2.description = 'CRON Scheduling Dashboard') | H3: ="insert into app.requesttype(requesttypeid, approute, description, longdescription) select (select max(r.requesttypeid) from app.requesttype r) + 1 requesttypeid, " & A3 & ", '" & D3 & "', '" & D3 & "' where not exists (select 1 from app.requesttype r2 where r2.approute = " & A3 & " );" -> insert into app.requesttype(requesttypeid, approute, description, longdescription) select (select max(r.requesttypeid) from app.requesttype r) + 1 requesttypeid, 53, 'in-transit-rma-asn-30-days', 'in-transit-rma-asn-30-days' where not exists (select 1 from app.requesttype r2 where r2.approute = 53 ); | I3: ="insert into app.requesttype(requesttypeid, approute, description, longdescription) select (select max(r.requesttypeid) from app.requesttype r) + 1 requesttypeid, " & B3 & ", '" & D3 & " Interactive', '" & D3 & " Interactive' where not exists (select 1 from app.requesttype r2 where r2.approute = " & B3 & " );" -> insert into app.requesttype(requesttypeid, approute, description, longdescription) select (select max(r.requesttypeid) from app.requesttype r) + 1 requesttypeid, 54, 'in-transit-rma-asn-30-days Interactive', 'in-transit-rma-asn-30-days Interactive' where not exists (select 1 from app.requesttype r2 where r2.approute = 54 ); | J3: ="insert into app.statemachinerepo(statemachine, description, requesttypeid) select '" & F3 & "-' || rt.description" & ", '" & F3 & "-' || rt.description" & ", rt.requesttypeid from app.requesttype rt where rt.description = '" & D3 & "' and not exists (select 1 from app.statemachinerepo sr where sr.description = '" & F3 & "-" & D3 & "');" -> insert into app.statemachinerepo(statemachine, description, requesttypeid) select 'tbd-' || rt.description, 'tbd-' || rt.description, rt.requesttypeid from app.requesttype rt where rt.description = 'in-transit-rma-asn-30-days' and not exists (select 1 from app.statemachinerepo sr where sr.description = 'tbd-in-transit-rma-asn-30-days'); | K3: {="insert into app.cronaction (CronTaskId, CronActionTypeId, Payload, CreatedBy, LastUpdatedBy) select c.crontaskid, cat.CronActionTypeId,'{""EmailTextOnError"":""tbd"",""TaskName"":""" & E3 & """, ""StateMachine"":""" & IF(ISNUMBER(SEARCH("DB Alert", E)), "wms-tools-state-machine-db-alert", """ wms-tools-state-machine-" & D3 & "" ) & """, "" Lambda "":"" & C2 & "", ""RequestType"":""" & D3 &"""}','sysuser', 'sysuser' from app.cronactiontype cat, app.crontasks c where c.description = '" & E3 & "' and not exists (select 1 from app.cronaction c2 where c2.crontaskid = c.crontaskid) and cat.description = 'NONE';"} -> insert into app.cronaction (CronTaskId, CronActionTypeId, Payload, CreatedBy, LastUpdatedBy) select c.crontaskid, cat.CronActionTypeId,'{"EmailTextOnError":"tbd","TaskName":"In Transit RMA ASN 30 Days", "StateMachine":"" wms-tools-state-machine-in-transit-rma-asn-30-days", " Lambda ":" & C2 & ", "RequestType":"in-transit-rma-asn-30-days"}','sysuser', 'sysuser' from app.cronactiontype cat, app.crontasks c where c.description = 'In Transit RMA ASN 30 Days' and not exists (select 1 from app.cronaction c2 where c2.crontaskid = c.crontaskid) and cat.description = 'NONE'; | L3: ="insert into app.cronaction (CronTaskId, CronActionTypeId, Payload, CreatedBy, LastUpdatedBy) select c.crontaskid, cat.CronActionTypeId,'{""EmailTextOnError"":""tbd"",""TaskName"":""" & E3 & """, ""StateMachine"":""" & IF(ISNUMBER(SEARCH("DB Alert", E3)), "wms-tools-state-machine-db-alert", """ wms-tools-state-machine-" & D3 & "" ) & """, "" Lambda "":""" & C3 & """, ""RequestType"":""" & D3 &"""}','sysuser', 'sysuser' from app.cronactiontype cat, app.crontasks c where c.description = '" & E3 & "' and not exists (select 1 from app.cronaction c2 where c2.crontaskid = c.crontaskid) and cat.description = 'NONE';" -> insert into app.cronaction (CronTaskId, CronActionTypeId, Payload, CreatedBy, LastUpdatedBy) select c.crontaskid, cat.CronActionTypeId,'{"EmailTextOnError":"tbd","TaskName":"In Transit RMA ASN 30 Days", "StateMachine":"" wms-tools-state-machine-in-transit-rma-asn-30-days", " Lambda ":"wms-tools-lambda-in-transit-rma-asn", "RequestType":"in-transit-rma-asn-30-days"}','sysuser', 'sysuser' from app.cronactiontype cat, app.crontasks c where c.description = 'In Transit RMA ASN 30 Days' and not exists (select 1 from app.cronaction c2 where c2.crontaskid = c.crontaskid) and cat.description = 'NONE';
A4: 55 | B4: =A4+1 -> 56 | C4: wms-tools-lambda-db-alert | D4: db-alert-order-no-desig-assign | E4: DB Alert: Orders No Designated or Assigned Shipments | F4: (not inserting for each new db alert, all DB Alerts using the same wms-tools-state-machine-db-alert) | G4: (select null) | H4: ="insert into app.requesttype(requesttypeid, approute, description, longdescription) select (select max(r.requesttypeid) from app.requesttype r) + 1 requesttypeid, " & A4 & ", '" & D4 & "', '" & D4 & "' where not exists (select 1 from app.requesttype r2 where r2.approute = " & A4 & " );" -> insert into app.requesttype(requesttypeid, approute, description, longdescription) select (select max(r.requesttypeid) from app.requesttype r) + 1 requesttypeid, 55, 'db-alert-order-no-desig-assign', 'db-alert-order-no-desig-assign' where not exists (select 1 from app.requesttype r2 where r2.approute = 55 ); | I4: ="insert into app.requesttype(requesttypeid, approute, description, longdescription) select (select max(r.requesttypeid) from app.requesttype r) + 1 requesttypeid, " & B4 & ", '" & D4 & " Interactive', '" & D4 & " Interactive' where not exists (select 1 from app.requesttype r2 where r2.approute = " & B4 & " );" -> insert into app.requesttype(requesttypeid, approute, description, longdescription) select (select max(r.requesttypeid) from app.requesttype r) + 1 requesttypeid, 56, 'db-alert-order-no-desig-assign Interactive', 'db-alert-order-no-desig-assign Interactive' where not exists (select 1 from app.requesttype r2 where r2.approute = 56 ); | J4: (not inserting for each new db alert, all DB Alerts using the same wms-tools-state-machine-db-alert) | K4: {="insert into app.cronaction (CronTaskId, CronActionTypeId, Payload, CreatedBy, LastUpdatedBy) select c.crontaskid, cat.CronActionTypeId,'{""EmailTextOnError"":""tbd"",""TaskName"":""" & E4 & """, ""StateMachine"":""" & IF(ISNUMBER(SEARCH("DB Alert", E)), "wms-tools-state-machine-db-alert", """ wms-tools-state-machine-" & D4 & "" ) & """, "" Lambda "":"" & C2 & "", ""RequestType"":""" & D4 &"""}','sysuser', 'sysuser' from app.cronactiontype cat, app.crontasks c where c.description = '" & E4 & "' and not exists (select 1 from app.cronaction c2 where c2.crontaskid = c.crontaskid) and cat.description = 'NONE';"} -> insert into app.cronaction (CronTaskId, CronActionTypeId, Payload, CreatedBy, LastUpdatedBy) select c.crontaskid, cat.CronActionTypeId,'{"EmailTextOnError":"tbd","TaskName":"DB Alert: Orders No Designated or Assigned Shipments", "StateMachine":"" wms-tools-state-machine-db-alert-order-no-desig-assign", " Lambda ":" & C2 & ", "RequestType":"db-alert-order-no-desig-assign"}','sysuser', 'sysuser' from app.cronactiontype cat, app.crontasks c where c.description = 'DB Alert: Orders No Designated or Assigned Shipments' and not exists (select 1 from app.cronaction c2 where c2.crontaskid = c.crontaskid) and cat.description = 'NONE'; | L4: ="insert into app.cronaction (CronTaskId, CronActionTypeId, Payload, CreatedBy, LastUpdatedBy) select c.crontaskid, cat.CronActionTypeId,'{""EmailTextOnError"":""tbd"",""TaskName"":""" & E4 & """, ""StateMachine"":""" & IF(ISNUMBER(SEARCH("DB Alert", E4)), "wms-tools-state-machine-db-alert", """ wms-tools-state-machine-" & D4 & "" ) & """, "" Lambda "":""" & C4 & """, ""RequestType"":""" & D4 &"""}','sysuser', 'sysuser' from app.cronactiontype cat, app.crontasks c where c.description = '" & E4 & "' and not exists (select 1 from app.cronaction c2 where c2.crontaskid = c.crontaskid) and cat.description = 'NONE';" -> insert into app.cronaction (CronTaskId, CronActionTypeId, Payload, CreatedBy, LastUpdatedBy) select c.crontaskid, cat.CronActionTypeId,'{"EmailTextOnError":"tbd","TaskName":"DB Alert: Orders No Designated or Assigned Shipments", "StateMachine":"wms-tools-state-machine-db-alert", " Lambda ":"wms-tools-lambda-db-alert", "RequestType":"db-alert-order-no-desig-assign"}','sysuser', 'sysuser' from app.cronactiontype cat, app.crontasks c where c.description = 'DB Alert: Orders No Designated or Assigned Shipments' and not exists (select 1 from app.cronaction c2 where c2.crontaskid = c.crontaskid) and cat.description = 'NONE'; | M4: All corrected (formula changed) but only for DB Alert records: For crontask query, D column (requestttype) was being used instead of E column (taskname) except for last variable. For cronaction query, same issue except for RequestType property in payload, in addition to not needing to append request type (colum D) to StateMachine and Lambda properties of payload.
A5: 57 | B5: =A5+1 -> 58 | C5: wms-tools-lambda-db-alert | D5: db-alert-order-no-desig | E5: DB Alert: Orders No Designated Shipments | F5: (not inserting for each new db alert, all DB Alerts using the same wms-tools-state-machine-db-alert) | G5: (select null) | H5: ="insert into app.requesttype(requesttypeid, approute, description, longdescription) select (select max(r.requesttypeid) from app.requesttype r) + 1 requesttypeid, " & A5 & ", '" & D5 & "', '" & D5 & "' where not exists (select 1 from app.requesttype r2 where r2.approute = " & A5 & " );" -> insert into app.requesttype(requesttypeid, approute, description, longdescription) select (select max(r.requesttypeid) from app.requesttype r) + 1 requesttypeid, 57, 'db-alert-order-no-desig', 'db-alert-order-no-desig' where not exists (select 1 from app.requesttype r2 where r2.approute = 57 ); | I5: ="insert into app.requesttype(requesttypeid, approute, description, longdescription) select (select max(r.requesttypeid) from app.requesttype r) + 1 requesttypeid, " & B5 & ", '" & D5 & " Interactive', '" & D5 & " Interactive' where not exists (select 1 from app.requesttype r2 where r2.approute = " & B5 & " );" -> insert into app.requesttype(requesttypeid, approute, description, longdescription) select (select max(r.requesttypeid) from app.requesttype r) + 1 requesttypeid, 58, 'db-alert-order-no-desig Interactive', 'db-alert-order-no-desig Interactive' where not exists (select 1 from app.requesttype r2 where r2.approute = 58 ); | J5: (not inserting for each new db alert, all DB Alerts using the same wms-tools-state-machine-db-alert) | K5: {="insert into app.cronaction (CronTaskId, CronActionTypeId, Payload, CreatedBy, LastUpdatedBy) select c.crontaskid, cat.CronActionTypeId,'{""EmailTextOnError"":""tbd"",""TaskName"":""" & E5 & """, ""StateMachine"":""" & IF(ISNUMBER(SEARCH("DB Alert", E)), "wms-tools-state-machine-db-alert", """ wms-tools-state-machine-" & D5 & "" ) & """, "" Lambda "":"" & C2 & "", ""RequestType"":""" & D5 &"""}','sysuser', 'sysuser' from app.cronactiontype cat, app.crontasks c where c.description = '" & E5 & "' and not exists (select 1 from app.cronaction c2 where c2.crontaskid = c.crontaskid) and cat.description = 'NONE';"} -> insert into app.cronaction (CronTaskId, CronActionTypeId, Payload, CreatedBy, LastUpdatedBy) select c.crontaskid, cat.CronActionTypeId,'{"EmailTextOnError":"tbd","TaskName":"DB Alert: Orders No Designated Shipments", "StateMachine":"" wms-tools-state-machine-db-alert-order-no-desig", " Lambda ":" & C2 & ", "RequestType":"db-alert-order-no-desig"}','sysuser', 'sysuser' from app.cronactiontype cat, app.crontasks c where c.description = 'DB Alert: Orders No Designated Shipments' and not exists (select 1 from app.cronaction c2 where c2.crontaskid = c.crontaskid) and cat.description = 'NONE'; | L5: ="insert into app.cronaction (CronTaskId, CronActionTypeId, Payload, CreatedBy, LastUpdatedBy) select c.crontaskid, cat.CronActionTypeId,'{""EmailTextOnError"":""tbd"",""TaskName"":""" & E5 & """, ""StateMachine"":""" & IF(ISNUMBER(SEARCH("DB Alert", E5)), "wms-tools-state-machine-db-alert", """ wms-tools-state-machine-" & D5 & "" ) & """, "" Lambda "":""" & C5 & """, ""RequestType"":""" & D5 &"""}','sysuser', 'sysuser' from app.cronactiontype cat, app.crontasks c where c.description = '" & E5 & "' and not exists (select 1 from app.cronaction c2 where c2.crontaskid = c.crontaskid) and cat.description = 'NONE';" -> insert into app.cronaction (CronTaskId, CronActionTypeId, Payload, CreatedBy, LastUpdatedBy) select c.crontaskid, cat.CronActionTypeId,'{"EmailTextOnError":"tbd","TaskName":"DB Alert: Orders No Designated Shipments", "StateMachine":"wms-tools-state-machine-db-alert", " Lambda ":"wms-tools-lambda-db-alert", "RequestType":"db-alert-order-no-desig"}','sysuser', 'sysuser' from app.cronactiontype cat, app.crontasks c where c.description = 'DB Alert: Orders No Designated Shipments' and not exists (select 1 from app.cronaction c2 where c2.crontaskid = c.crontaskid) and cat.description = 'NONE';
A6: 59 | B6: =A6+1 -> 60 | C6: wms-tools-lambda-db-alert | D6: db-alert-static-route-missing-threshold | E6: DB Alert: Static Route Missing Threshold Value | F6: (not inserting for each new db alert, all DB Alerts using the same wms-tools-state-machine-db-alert) | G6: (select null) | H6: ="insert into app.requesttype(requesttypeid, approute, description, longdescription) select (select max(r.requesttypeid) from app.requesttype r) + 1 requesttypeid, " & A6 & ", '" & D6 & "', '" & D6 & "' where not exists (select 1 from app.requesttype r2 where r2.approute = " & A6 & " );" -> insert into app.requesttype(requesttypeid, approute, description, longdescription) select (select max(r.requesttypeid) from app.requesttype r) + 1 requesttypeid, 59, 'db-alert-static-route-missing-threshold', 'db-alert-static-route-missing-threshold' where not exists (select 1 from app.requesttype r2 where r2.approute = 59 ); | I6: ="insert into app.requesttype(requesttypeid, approute, description, longdescription) select (select max(r.requesttypeid) from app.requesttype r) + 1 requesttypeid, " & B6 & ", '" & D6 & " Interactive', '" & D6 & " Interactive' where not exists (select 1 from app.requesttype r2 where r2.approute = " & B6 & " );" -> insert into app.requesttype(requesttypeid, approute, description, longdescription) select (select max(r.requesttypeid) from app.requesttype r) + 1 requesttypeid, 60, 'db-alert-static-route-missing-threshold Interactive', 'db-alert-static-route-missing-threshold Interactive' where not exists (select 1 from app.requesttype r2 where r2.approute = 60 ); | J6: (not inserting for each new db alert, all DB Alerts using the same wms-tools-state-machine-db-alert) | K6: {="insert into app.cronaction (CronTaskId, CronActionTypeId, Payload, CreatedBy, LastUpdatedBy) select c.crontaskid, cat.CronActionTypeId,'{""EmailTextOnError"":""tbd"",""TaskName"":""" & E6 & """, ""StateMachine"":""" & IF(ISNUMBER(SEARCH("DB Alert", E)), "wms-tools-state-machine-db-alert", """ wms-tools-state-machine-" & D6 & "" ) & """, "" Lambda "":"" & C2 & "", ""RequestType"":""" & D6 &"""}','sysuser', 'sysuser' from app.cronactiontype cat, app.crontasks c where c.description = '" & E6 & "' and not exists (select 1 from app.cronaction c2 where c2.crontaskid = c.crontaskid) and cat.description = 'NONE';"} -> insert into app.cronaction (CronTaskId, CronActionTypeId, Payload, CreatedBy, LastUpdatedBy) select c.crontaskid, cat.CronActionTypeId,'{"EmailTextOnError":"tbd","TaskName":"DB Alert: Static Route Missing Threshold Value", "StateMachine":"" wms-tools-state-machine-db-alert-static-route-missing-threshold", " Lambda ":" & C2 & ", "RequestType":"db-alert-static-route-missing-threshold"}','sysuser', 'sysuser' from app.cronactiontype cat, app.crontasks c where c.description = 'DB Alert: Static Route Missing Threshold Value' and not exists (select 1 from app.cronaction c2 where c2.crontaskid = c.crontaskid) and cat.description = 'NONE'; | L6: ="insert into app.cronaction (CronTaskId, CronActionTypeId, Payload, CreatedBy, LastUpdatedBy) select c.crontaskid, cat.CronActionTypeId,'{""EmailTextOnError"":""tbd"",""TaskName"":""" & E6 & """, ""StateMachine"":""" & IF(ISNUMBER(SEARCH("DB Alert", E6)), "wms-tools-state-machine-db-alert", """ wms-tools-state-machine-" & D6 & "" ) & """, "" Lambda "":""" & C6 & """, ""RequestType"":""" & D6 &"""}','sysuser', 'sysuser' from app.cronactiontype cat, app.crontasks c where c.description = '" & E6 & "' and not exists (select 1 from app.cronaction c2 where c2.crontaskid = c.crontaskid) and cat.description = 'NONE';" -> insert into app.cronaction (CronTaskId, CronActionTypeId, Payload, CreatedBy, LastUpdatedBy) select c.crontaskid, cat.CronActionTypeId,'{"EmailTextOnError":"tbd","TaskName":"DB Alert: Static Route Missing Threshold Value", "StateMachine":"wms-tools-state-machine-db-alert", " Lambda ":"wms-tools-lambda-db-alert", "RequestType":"db-alert-static-route-missing-threshold"}','sysuser', 'sysuser' from app.cronactiontype cat, app.crontasks c where c.description = 'DB Alert: Static Route Missing Threshold Value' and not exists (select 1 from app.cronaction c2 where c2.crontaskid = c.crontaskid) and cat.description = 'NONE'; | M6: All corrected (formula changed) but only for DB Alert records: For crontask query, D column (requestttype) was being used instead of E column (taskname) except for last variable. For cronaction query, same issue except for RequestType property in payload, in addition to not needing to append request type (colum D) to StateMachine and Lambda properties of payload.
A7: 61 | B7: =A7+1 -> 62 | C7: wms-tools-lambda-oracle-db-alert | D7: db-alert-order-not-process-15m | E7: DB Alert: Orders Not Process In Host > 15 Minutes | F7: tbd | G7: (select null) | H7: ="insert into app.requesttype(requesttypeid, approute, description, longdescription) select (select max(r.requesttypeid) from app.requesttype r) + 1 requesttypeid, " & A7 & ", '" & D7 & "', '" & D7 & "' where not exists (select 1 from app.requesttype r2 where r2.approute = " & A7 & " );" -> insert into app.requesttype(requesttypeid, approute, description, longdescription) select (select max(r.requesttypeid) from app.requesttype r) + 1 requesttypeid, 61, 'db-alert-order-not-process-15m', 'db-alert-order-not-process-15m' where not exists (select 1 from app.requesttype r2 where r2.approute = 61 ); | I7: ="insert into app.requesttype(requesttypeid, approute, description, longdescription) select (select max(r.requesttypeid) from app.requesttype r) + 1 requesttypeid, " & B7 & ", '" & D7 & " Interactive', '" & D7 & " Interactive' where not exists (select 1 from app.requesttype r2 where r2.approute = " & B7 & " );" -> insert into app.requesttype(requesttypeid, approute, description, longdescription) select (select max(r.requesttypeid) from app.requesttype r) + 1 requesttypeid, 62, 'db-alert-order-not-process-15m Interactive', 'db-alert-order-not-process-15m Interactive' where not exists (select 1 from app.requesttype r2 where r2.approute = 62 ); | J7: ="insert into app.statemachinerepo(statemachine, description, requesttypeid) select '" & F7 & "-' || rt.description" & ", '" & F7 & "-' || rt.description" & ", rt.requesttypeid from app.requesttype rt where rt.description = '" & D7 & "' and not exists (select 1 from app.statemachinerepo sr where sr.description = '" & F7 & "-" & D7 & "');" -> insert into app.statemachinerepo(statemachine, description, requesttypeid) select 'tbd-' || rt.description, 'tbd-' || rt.description, rt.requesttypeid from app.requesttype rt where rt.description = 'db-alert-order-not-process-15m' and not exists (select 1 from app.statemachinerepo sr where sr.description = 'tbd-db-alert-order-not-process-15m'); | K7: {="insert into app.cronaction (CronTaskId, CronActionTypeId, Payload, CreatedBy, LastUpdatedBy) select c.crontaskid, cat.CronActionTypeId,'{""EmailTextOnError"":""tbd"",""TaskName"":""" & E7 & """, ""StateMachine"":""" & IF(ISNUMBER(SEARCH("DB Alert", E)), "wms-tools-state-machine-db-alert", """ wms-tools-state-machine-" & D7 & "" ) & """, "" Lambda "":"" & C2 & "", ""RequestType"":""" & D7 &"""}','sysuser', 'sysuser' from app.cronactiontype cat, app.crontasks c where c.description = '" & E7 & "' and not exists (select 1 from app.cronaction c2 where c2.crontaskid = c.crontaskid) and cat.description = 'NONE';"} -> insert into app.cronaction (CronTaskId, CronActionTypeId, Payload, CreatedBy, LastUpdatedBy) select c.crontaskid, cat.CronActionTypeId,'{"EmailTextOnError":"tbd","TaskName":"DB Alert: Orders Not Process In Host > 15 Minutes", "StateMachine":"" wms-tools-state-machine-db-alert-order-not-process-15m", " Lambda ":" & C2 & ", "RequestType":"db-alert-order-not-process-15m"}','sysuser', 'sysuser' from app.cronactiontype cat, app.crontasks c where c.description = 'DB Alert: Orders Not Process In Host > 15 Minutes' and not exists (select 1 from app.cronaction c2 where c2.crontaskid = c.crontaskid) and cat.description = 'NONE'; | L7: ="insert into app.cronaction (CronTaskId, CronActionTypeId, Payload, CreatedBy, LastUpdatedBy) select c.crontaskid, cat.CronActionTypeId,'{""EmailTextOnError"":""tbd"",""TaskName"":""" & E7 & """, ""StateMachine"":""" & IF(ISNUMBER(SEARCH("DB Alert", E7)), "wms-tools-state-machine-db-alert", """ wms-tools-state-machine-" & D7 & "" ) & """, "" Lambda "":""" & C7 & """, ""RequestType"":""" & D7 &"""}','sysuser', 'sysuser' from app.cronactiontype cat, app.crontasks c where c.description = '" & E7 & "' and not exists (select 1 from app.cronaction c2 where c2.crontaskid = c.crontaskid) and cat.description = 'NONE';" -> insert into app.cronaction (CronTaskId, CronActionTypeId, Payload, CreatedBy, LastUpdatedBy) select c.crontaskid, cat.CronActionTypeId,'{"EmailTextOnError":"tbd","TaskName":"DB Alert: Orders Not Process In Host > 15 Minutes", "StateMachine":"wms-tools-state-machine-db-alert", " Lambda ":"wms-tools-lambda-oracle-db-alert", "RequestType":"db-alert-order-not-process-15m"}','sysuser', 'sysuser' from app.cronactiontype cat, app.crontasks c where c.description = 'DB Alert: Orders Not Process In Host > 15 Minutes' and not exists (select 1 from app.cronaction c2 where c2.crontaskid = c.crontaskid) and cat.description = 'NONE'; | M7: ORDERS NOT PROCESS IN HOST > 15 MINUTES
A8: 63 | B8: =A8+1 -> 64 | C8: wms-tools-lambda-lpns-no-task-api-fail | D8: lpns-no-task-api-fail | E8: Allocated Lpns With No Open Task Details Api Failure | F8: tbd | G8: (select rt2.requesttypeid from app.requesttype rt2 where rt2.description = 'CRON Scheduling Dashboard') | H8: ="insert into app.requesttype(requesttypeid, approute, description, longdescription) select (select max(r.requesttypeid) from app.requesttype r) + 1 requesttypeid, " & A8 & ", '" & D8 & "', '" & D8 & "' where not exists (select 1 from app.requesttype r2 where r2.approute = " & A8 & " );" -> insert into app.requesttype(requesttypeid, approute, description, longdescription) select (select max(r.requesttypeid) from app.requesttype r) + 1 requesttypeid, 63, 'lpns-no-task-api-fail', 'lpns-no-task-api-fail' where not exists (select 1 from app.requesttype r2 where r2.approute = 63 ); | I8: ="insert into app.requesttype(requesttypeid, approute, description, longdescription) select (select max(r.requesttypeid) from app.requesttype r) + 1 requesttypeid, " & B8 & ", '" & D8 & " Interactive', '" & D8 & " Interactive' where not exists (select 1 from app.requesttype r2 where r2.approute = " & B8 & " );" -> insert into app.requesttype(requesttypeid, approute, description, longdescription) select (select max(r.requesttypeid) from app.requesttype r) + 1 requesttypeid, 64, 'lpns-no-task-api-fail Interactive', 'lpns-no-task-api-fail Interactive' where not exists (select 1 from app.requesttype r2 where r2.approute = 64 ); | J8: ="insert into app.statemachinerepo(statemachine, description, requesttypeid) select '" & F8 & "-' || rt.description" & ", '" & F8 & "-' || rt.description" & ", rt.requesttypeid from app.requesttype rt where rt.description = '" & D8 & "' and not exists (select 1 from app.statemachinerepo sr where sr.description = '" & F8 & "-" & D8 & "');" -> insert into app.statemachinerepo(statemachine, description, requesttypeid) select 'tbd-' || rt.description, 'tbd-' || rt.description, rt.requesttypeid from app.requesttype rt where rt.description = 'lpns-no-task-api-fail' and not exists (select 1 from app.statemachinerepo sr where sr.description = 'tbd-lpns-no-task-api-fail'); | K8: {="insert into app.cronaction (CronTaskId, CronActionTypeId, Payload, CreatedBy, LastUpdatedBy) select c.crontaskid, cat.CronActionTypeId,'{""EmailTextOnError"":""tbd"",""TaskName"":""" & E8 & """, ""StateMachine"":""" & IF(ISNUMBER(SEARCH("DB Alert", E)), "wms-tools-state-machine-db-alert", """ wms-tools-state-machine-" & D8 & "" ) & """, "" Lambda "":"" & C2 & "", ""RequestType"":""" & D8 &"""}','sysuser', 'sysuser' from app.cronactiontype cat, app.crontasks c where c.description = '" & E8 & "' and not exists (select 1 from app.cronaction c2 where c2.crontaskid = c.crontaskid) and cat.description = 'NONE';"} -> insert into app.cronaction (CronTaskId, CronActionTypeId, Payload, CreatedBy, LastUpdatedBy) select c.crontaskid, cat.CronActionTypeId,'{"EmailTextOnError":"tbd","TaskName":"Allocated Lpns With No Open Task Details Api Failure", "StateMachine":"" wms-tools-state-machine-lpns-no-task-api-fail", " Lambda ":" & C2 & ", "RequestType":"lpns-no-task-api-fail"}','sysuser', 'sysuser' from app.cronactiontype cat, app.crontasks c where c.description = 'Allocated Lpns With No Open Task Details Api Failure' and not exists (select 1 from app.cronaction c2 where c2.crontaskid = c.crontaskid) and cat.description = 'NONE'; | L8: ="insert into app.cronaction (CronTaskId, CronActionTypeId, Payload, CreatedBy, LastUpdatedBy) select c.crontaskid, cat.CronActionTypeId,'{""EmailTextOnError"":""tbd"",""TaskName"":""" & E8 & """, ""StateMachine"":""" & IF(ISNUMBER(SEARCH("DB Alert", E8)), "wms-tools-state-machine-db-alert", """ wms-tools-state-machine-" & D8 & "" ) & """, "" Lambda "":""" & C8 & """, ""RequestType"":""" & D8 &"""}','sysuser', 'sysuser' from app.cronactiontype cat, app.crontasks c where c.description = '" & E8 & "' and not exists (select 1 from app.cronaction c2 where c2.crontaskid = c.crontaskid) and cat.description = 'NONE';" -> insert into app.cronaction (CronTaskId, CronActionTypeId, Payload, CreatedBy, LastUpdatedBy) select c.crontaskid, cat.CronActionTypeId,'{"EmailTextOnError":"tbd","TaskName":"Allocated Lpns With No Open Task Details Api Failure", "StateMachine":"" wms-tools-state-machine-lpns-no-task-api-fail", " Lambda ":"wms-tools-lambda-lpns-no-task-api-fail", "RequestType":"lpns-no-task-api-fail"}','sysuser', 'sysuser' from app.cronactiontype cat, app.crontasks c where c.description = 'Allocated Lpns With No Open Task Details Api Failure' and not exists (select 1 from app.cronaction c2 where c2.crontaskid = c.crontaskid) and cat.description = 'NONE'; | M8: ALLOCATED LPNS WITH NO OPEN TASK DETAILS API FAILURE
A9: 65 | B9: =A9+1 -> 66 | C9: wms-tools-lambda-fs-alpha-asn-error | D9: fs-alpha-asn-error | E9: FS: Alpha Asn Error | F9: tbd | G9: (select null) | H9: ="insert into app.requesttype(requesttypeid, approute, description, longdescription) select (select max(r.requesttypeid) from app.requesttype r) + 1 requesttypeid, " & A9 & ", '" & D9 & "', '" & D9 & "' where not exists (select 1 from app.requesttype r2 where r2.approute = " & A9 & " );" -> insert into app.requesttype(requesttypeid, approute, description, longdescription) select (select max(r.requesttypeid) from app.requesttype r) + 1 requesttypeid, 65, 'fs-alpha-asn-error', 'fs-alpha-asn-error' where not exists (select 1 from app.requesttype r2 where r2.approute = 65 ); | I9: ="insert into app.requesttype(requesttypeid, approute, description, longdescription) select (select max(r.requesttypeid) from app.requesttype r) + 1 requesttypeid, " & B9 & ", '" & D9 & " Interactive', '" & D9 & " Interactive' where not exists (select 1 from app.requesttype r2 where r2.approute = " & B9 & " );" -> insert into app.requesttype(requesttypeid, approute, description, longdescription) select (select max(r.requesttypeid) from app.requesttype r) + 1 requesttypeid, 66, 'fs-alpha-asn-error Interactive', 'fs-alpha-asn-error Interactive' where not exists (select 1 from app.requesttype r2 where r2.approute = 66 ); | J9: ="insert into app.statemachinerepo(statemachine, description, requesttypeid) select '" & F9 & "-' || rt.description" & ", '" & F9 & "-' || rt.description" & ", rt.requesttypeid from app.requesttype rt where rt.description = '" & D9 & "' and not exists (select 1 from app.statemachinerepo sr where sr.description = '" & F9 & "-" & D9 & "');" -> insert into app.statemachinerepo(statemachine, description, requesttypeid) select 'tbd-' || rt.description, 'tbd-' || rt.description, rt.requesttypeid from app.requesttype rt where rt.description = 'fs-alpha-asn-error' and not exists (select 1 from app.statemachinerepo sr where sr.description = 'tbd-fs-alpha-asn-error'); | K9: {="insert into app.cronaction (CronTaskId, CronActionTypeId, Payload, CreatedBy, LastUpdatedBy) select c.crontaskid, cat.CronActionTypeId,'{""EmailTextOnError"":""tbd"",""TaskName"":""" & E9 & """, ""StateMachine"":""" & IF(ISNUMBER(SEARCH("DB Alert", E)), "wms-tools-state-machine-db-alert", """ wms-tools-state-machine-" & D9 & "" ) & """, "" Lambda "":"" & C2 & "", ""RequestType"":""" & D9 &"""}','sysuser', 'sysuser' from app.cronactiontype cat, app.crontasks c where c.description = '" & E9 & "' and not exists (select 1 from app.cronaction c2 where c2.crontaskid = c.crontaskid) and cat.description = 'NONE';"} -> insert into app.cronaction (CronTaskId, CronActionTypeId, Payload, CreatedBy, LastUpdatedBy) select c.crontaskid, cat.CronActionTypeId,'{"EmailTextOnError":"tbd","TaskName":"FS: Alpha Asn Error", "StateMachine":"" wms-tools-state-machine-fs-alpha-asn-error", " Lambda ":" & C2 & ", "RequestType":"fs-alpha-asn-error"}','sysuser', 'sysuser' from app.cronactiontype cat, app.crontasks c where c.description = 'FS: Alpha Asn Error' and not exists (select 1 from app.cronaction c2 where c2.crontaskid = c.crontaskid) and cat.description = 'NONE'; | L9: ="insert into app.cronaction (CronTaskId, CronActionTypeId, Payload, CreatedBy, LastUpdatedBy) select c.crontaskid, cat.CronActionTypeId,'{""EmailTextOnError"":""tbd"",""TaskName"":""" & E9 & """, ""StateMachine"":""" & IF(ISNUMBER(SEARCH("DB Alert", E9)), "wms-tools-state-machine-db-alert", """ wms-tools-state-machine-" & D9 & "" ) & """, "" Lambda "":""" & C9 & """, ""RequestType"":""" & D9 &"""}','sysuser', 'sysuser' from app.cronactiontype cat, app.crontasks c where c.description = '" & E9 & "' and not exists (select 1 from app.cronaction c2 where c2.crontaskid = c.crontaskid) and cat.description = 'NONE';" -> insert into app.cronaction (CronTaskId, CronActionTypeId, Payload, CreatedBy, LastUpdatedBy) select c.crontaskid, cat.CronActionTypeId,'{"EmailTextOnError":"tbd","TaskName":"FS: Alpha Asn Error", "StateMachine":"" wms-tools-state-machine-fs-alpha-asn-error", " Lambda ":"wms-tools-lambda-fs-alpha-asn-error", "RequestType":"fs-alpha-asn-error"}','sysuser', 'sysuser' from app.cronactiontype cat, app.crontasks c where c.description = 'FS: Alpha Asn Error' and not exists (select 1 from app.cronaction c2 where c2.crontaskid = c.crontaskid) and cat.description = 'NONE'; | M9: ALPHA ASN ERROR
A10: 67 | B10: =A10+1 -> 68 | C10: wms-tools-lambda-fs-alpha-open-err-asn | D10: fs-alpha-open-err-asn | E10: FS: Alpha Open/Error Asn | F10: tbd | G10: (select null) | H10: ="insert into app.requesttype(requesttypeid, approute, description, longdescription) select (select max(r.requesttypeid) from app.requesttype r) + 1 requesttypeid, " & A10 & ", '" & D10 & "', '" & D10 & "' where not exists (select 1 from app.requesttype r2 where r2.approute = " & A10 & " );" -> insert into app.requesttype(requesttypeid, approute, description, longdescription) select (select max(r.requesttypeid) from app.requesttype r) + 1 requesttypeid, 67, 'fs-alpha-open-err-asn', 'fs-alpha-open-err-asn' where not exists (select 1 from app.requesttype r2 where r2.approute = 67 ); | I10: ="insert into app.requesttype(requesttypeid, approute, description, longdescription) select (select max(r.requesttypeid) from app.requesttype r) + 1 requesttypeid, " & B10 & ", '" & D10 & " Interactive', '" & D10 & " Interactive' where not exists (select 1 from app.requesttype r2 where r2.approute = " & B10 & " );" -> insert into app.requesttype(requesttypeid, approute, description, longdescription) select (select max(r.requesttypeid) from app.requesttype r) + 1 requesttypeid, 68, 'fs-alpha-open-err-asn Interactive', 'fs-alpha-open-err-asn Interactive' where not exists (select 1 from app.requesttype r2 where r2.approute = 68 ); | J10: ="insert into app.statemachinerepo(statemachine, description, requesttypeid) select '" & F10 & "-' || rt.description" & ", '" & F10 & "-' || rt.description" & ", rt.requesttypeid from app.requesttype rt where rt.description = '" & D10 & "' and not exists (select 1 from app.statemachinerepo sr where sr.description = '" & F10 & "-" & D10 & "');" -> insert into app.statemachinerepo(statemachine, description, requesttypeid) select 'tbd-' || rt.description, 'tbd-' || rt.description, rt.requesttypeid from app.requesttype rt where rt.description = 'fs-alpha-open-err-asn' and not exists (select 1 from app.statemachinerepo sr where sr.description = 'tbd-fs-alpha-open-err-asn'); | K10: {="insert into app.cronaction (CronTaskId, CronActionTypeId, Payload, CreatedBy, LastUpdatedBy) select c.crontaskid, cat.CronActionTypeId,'{""EmailTextOnError"":""tbd"",""TaskName"":""" & E10 & """, ""StateMachine"":""" & IF(ISNUMBER(SEARCH("DB Alert", E)), "wms-tools-state-machine-db-alert", """ wms-tools-state-machine-" & D10 & "" ) & """, "" Lambda "":"" & C2 & "", ""RequestType"":""" & D10 &"""}','sysuser', 'sysuser' from app.cronactiontype cat, app.crontasks c where c.description = '" & E10 & "' and not exists (select 1 from app.cronaction c2 where c2.crontaskid = c.crontaskid) and cat.description = 'NONE';"} -> insert into app.cronaction (CronTaskId, CronActionTypeId, Payload, CreatedBy, LastUpdatedBy) select c.crontaskid, cat.CronActionTypeId,'{"EmailTextOnError":"tbd","TaskName":"FS: Alpha Open/Error Asn", "StateMachine":"" wms-tools-state-machine-fs-alpha-open-err-asn", " Lambda ":" & C2 & ", "RequestType":"fs-alpha-open-err-asn"}','sysuser', 'sysuser' from app.cronactiontype cat, app.crontasks c where c.description = 'FS: Alpha Open/Error Asn' and not exists (select 1 from app.cronaction c2 where c2.crontaskid = c.crontaskid) and cat.description = 'NONE'; | L10: ="insert into app.cronaction (CronTaskId, CronActionTypeId, Payload, CreatedBy, LastUpdatedBy) select c.crontaskid, cat.CronActionTypeId,'{""EmailTextOnError"":""tbd"",""TaskName"":""" & E10 & """, ""StateMachine"":""" & IF(ISNUMBER(SEARCH("DB Alert", E10)), "wms-tools-state-machine-db-alert", """ wms-tools-state-machine-" & D10 & "" ) & """, "" Lambda "":""" & C10 & """, ""RequestType"":""" & D10 &"""}','sysuser', 'sysuser' from app.cronactiontype cat, app.crontasks c where c.description = '" & E10 & "' and not exists (select 1 from app.cronaction c2 where c2.crontaskid = c.crontaskid) and cat.description = 'NONE';" -> insert into app.cronaction (CronTaskId, CronActionTypeId, Payload, CreatedBy, LastUpdatedBy) select c.crontaskid, cat.CronActionTypeId,'{"EmailTextOnError":"tbd","TaskName":"FS: Alpha Open/Error Asn", "StateMachine":"" wms-tools-state-machine-fs-alpha-open-err-asn", " Lambda ":"wms-tools-lambda-fs-alpha-open-err-asn", "RequestType":"fs-alpha-open-err-asn"}','sysuser', 'sysuser' from app.cronactiontype cat, app.crontasks c where c.description = 'FS: Alpha Open/Error Asn' and not exists (select 1 from app.cronaction c2 where c2.crontaskid = c.crontaskid) and cat.description = 'NONE'; | M10: ALPHA OPEN/ERROR ASN
A11: 69 | B11: =A11+1 -> 70 | C11: wms-tools-lambda-fs-alpha-open-returns | D11: fs-alpha-open-returns | E11: FS: Alpha Open Returns | F11: tbd | G11: (select null) | H11: ="insert into app.requesttype(requesttypeid, approute, description, longdescription) select (select max(r.requesttypeid) from app.requesttype r) + 1 requesttypeid, " & A11 & ", '" & D11 & "', '" & D11 & "' where not exists (select 1 from app.requesttype r2 where r2.approute = " & A11 & " );" -> insert into app.requesttype(requesttypeid, approute, description, longdescription) select (select max(r.requesttypeid) from app.requesttype r) + 1 requesttypeid, 69, 'fs-alpha-open-returns', 'fs-alpha-open-returns' where not exists (select 1 from app.requesttype r2 where r2.approute = 69 ); | I11: ="insert into app.requesttype(requesttypeid, approute, description, longdescription) select (select max(r.requesttypeid) from app.requesttype r) + 1 requesttypeid, " & B11 & ", '" & D11 & " Interactive', '" & D11 & " Interactive' where not exists (select 1 from app.requesttype r2 where r2.approute = " & B11 & " );" -> insert into app.requesttype(requesttypeid, approute, description, longdescription) select (select max(r.requesttypeid) from app.requesttype r) + 1 requesttypeid, 70, 'fs-alpha-open-returns Interactive', 'fs-alpha-open-returns Interactive' where not exists (select 1 from app.requesttype r2 where r2.approute = 70 ); | J11: ="insert into app.statemachinerepo(statemachine, description, requesttypeid) select '" & F11 & "-' || rt.description" & ", '" & F11 & "-' || rt.description" & ", rt.requesttypeid from app.requesttype rt where rt.description = '" & D11 & "' and not exists (select 1 from app.statemachinerepo sr where sr.description = '" & F11 & "-" & D11 & "');" -> insert into app.statemachinerepo(statemachine, description, requesttypeid) select 'tbd-' || rt.description, 'tbd-' || rt.description, rt.requesttypeid from app.requesttype rt where rt.description = 'fs-alpha-open-returns' and not exists (select 1 from app.statemachinerepo sr where sr.description = 'tbd-fs-alpha-open-returns'); | K11: {="insert into app.cronaction (CronTaskId, CronActionTypeId, Payload, CreatedBy, LastUpdatedBy) select c.crontaskid, cat.CronActionTypeId,'{""EmailTextOnError"":""tbd"",""TaskName"":""" & E11 & """, ""StateMachine"":""" & IF(ISNUMBER(SEARCH("DB Alert", E)), "wms-tools-state-machine-db-alert", """ wms-tools-state-machine-" & D11 & "" ) & """, "" Lambda "":"" & C2 & "", ""RequestType"":""" & D11 &"""}','sysuser', 'sysuser' from app.cronactiontype cat, app.crontasks c where c.description = '" & E11 & "' and not exists (select 1 from app.cronaction c2 where c2.crontaskid = c.crontaskid) and cat.description = 'NONE';"} -> insert into app.cronaction (CronTaskId, CronActionTypeId, Payload, CreatedBy, LastUpdatedBy) select c.crontaskid, cat.CronActionTypeId,'{"EmailTextOnError":"tbd","TaskName":"FS: Alpha Open Returns", "StateMachine":"" wms-tools-state-machine-fs-alpha-open-returns", " Lambda ":" & C2 & ", "RequestType":"fs-alpha-open-returns"}','sysuser', 'sysuser' from app.cronactiontype cat, app.crontasks c where c.description = 'FS: Alpha Open Returns' and not exists (select 1 from app.cronaction c2 where c2.crontaskid = c.crontaskid) and cat.description = 'NONE'; | L11: ="insert into app.cronaction (CronTaskId, CronActionTypeId, Payload, CreatedBy, LastUpdatedBy) select c.crontaskid, cat.CronActionTypeId,'{""EmailTextOnError"":""tbd"",""TaskName"":""" & E11 & """, ""StateMachine"":""" & IF(ISNUMBER(SEARCH("DB Alert", E11)), "wms-tools-state-machine-db-alert", """ wms-tools-state-machine-" & D11 & "" ) & """, "" Lambda "":""" & C11 & """, ""RequestType"":""" & D11 &"""}','sysuser', 'sysuser' from app.cronactiontype cat, app.crontasks c where c.description = '" & E11 & "' and not exists (select 1 from app.cronaction c2 where c2.crontaskid = c.crontaskid) and cat.description = 'NONE';" -> insert into app.cronaction (CronTaskId, CronActionTypeId, Payload, CreatedBy, LastUpdatedBy) select c.crontaskid, cat.CronActionTypeId,'{"EmailTextOnError":"tbd","TaskName":"FS: Alpha Open Returns", "StateMachine":"" wms-tools-state-machine-fs-alpha-open-returns", " Lambda ":"wms-tools-lambda-fs-alpha-open-returns", "RequestType":"fs-alpha-open-returns"}','sysuser', 'sysuser' from app.cronactiontype cat, app.crontasks c where c.description = 'FS: Alpha Open Returns' and not exists (select 1 from app.cronaction c2 where c2.crontaskid = c.crontaskid) and cat.description = 'NONE'; | M11: ALPHA OPEN RETURNS
A12: 71 | B12: =A12+1 -> 72 | C12: wms-tools-lambda-divert-conf-down | D12: divert-conf-down | E12: Divert Confirmation Down | F12: tbd | G12: (select rt2.requesttypeid from app.requesttype rt2 where rt2.description = 'CRON Scheduling Dashboard') | H12: ="insert into app.requesttype(requesttypeid, approute, description, longdescription) select (select max(r.requesttypeid) from app.requesttype r) + 1 requesttypeid, " & A12 & ", '" & D12 & "', '" & D12 & "' where not exists (select 1 from app.requesttype r2 where r2.approute = " & A12 & " );" -> insert into app.requesttype(requesttypeid, approute, description, longdescription) select (select max(r.requesttypeid) from app.requesttype r) + 1 requesttypeid, 71, 'divert-conf-down', 'divert-conf-down' where not exists (select 1 from app.requesttype r2 where r2.approute = 71 ); | I12: ="insert into app.requesttype(requesttypeid, approute, description, longdescription) select (select max(r.requesttypeid) from app.requesttype r) + 1 requesttypeid, " & B12 & ", '" & D12 & " Interactive', '" & D12 & " Interactive' where not exists (select 1 from app.requesttype r2 where r2.approute = " & B12 & " );" -> insert into app.requesttype(requesttypeid, approute, description, longdescription) select (select max(r.requesttypeid) from app.requesttype r) + 1 requesttypeid, 72, 'divert-conf-down Interactive', 'divert-conf-down Interactive' where not exists (select 1 from app.requesttype r2 where r2.approute = 72 ); | J12: ="insert into app.statemachinerepo(statemachine, description, requesttypeid) select '" & F12 & "-' || rt.description" & ", '" & F12 & "-' || rt.description" & ", rt.requesttypeid from app.requesttype rt where rt.description = '" & D12 & "' and not exists (select 1 from app.statemachinerepo sr where sr.description = '" & F12 & "-" & D12 & "');" -> insert into app.statemachinerepo(statemachine, description, requesttypeid) select 'tbd-' || rt.description, 'tbd-' || rt.description, rt.requesttypeid from app.requesttype rt where rt.description = 'divert-conf-down' and not exists (select 1 from app.statemachinerepo sr where sr.description = 'tbd-divert-conf-down'); | K12: {="insert into app.cronaction (CronTaskId, CronActionTypeId, Payload, CreatedBy, LastUpdatedBy) select c.crontaskid, cat.CronActionTypeId,'{""EmailTextOnError"":""tbd"",""TaskName"":""" & E12 & """, ""StateMachine"":""" & IF(ISNUMBER(SEARCH("DB Alert", E)), "wms-tools-state-machine-db-alert", """ wms-tools-state-machine-" & D12 & "" ) & """, "" Lambda "":"" & C2 & "", ""RequestType"":""" & D12 &"""}','sysuser', 'sysuser' from app.cronactiontype cat, app.crontasks c where c.description = '" & E12 & "' and not exists (select 1 from app.cronaction c2 where c2.crontaskid = c.crontaskid) and cat.description = 'NONE';"} -> insert into app.cronaction (CronTaskId, CronActionTypeId, Payload, CreatedBy, LastUpdatedBy) select c.crontaskid, cat.CronActionTypeId,'{"EmailTextOnError":"tbd","TaskName":"Divert Confirmation Down", "StateMachine":"" wms-tools-state-machine-divert-conf-down", " Lambda ":" & C2 & ", "RequestType":"divert-conf-down"}','sysuser', 'sysuser' from app.cronactiontype cat, app.crontasks c where c.description = 'Divert Confirmation Down' and not exists (select 1 from app.cronaction c2 where c2.crontaskid = c.crontaskid) and cat.description = 'NONE'; | L12: ="insert into app.cronaction (CronTaskId, CronActionTypeId, Payload, CreatedBy, LastUpdatedBy) select c.crontaskid, cat.CronActionTypeId,'{""EmailTextOnError"":""tbd"",""TaskName"":""" & E12 & """, ""StateMachine"":""" & IF(ISNUMBER(SEARCH("DB Alert", E12)), "wms-tools-state-machine-db-alert", """ wms-tools-state-machine-" & D12 & "" ) & """, "" Lambda "":""" & C12 & """, ""RequestType"":""" & D12 &"""}','sysuser', 'sysuser' from app.cronactiontype cat, app.crontasks c where c.description = '" & E12 & "' and not exists (select 1 from app.cronaction c2 where c2.crontaskid = c.crontaskid) and cat.description = 'NONE';" -> insert into app.cronaction (CronTaskId, CronActionTypeId, Payload, CreatedBy, LastUpdatedBy) select c.crontaskid, cat.CronActionTypeId,'{"EmailTextOnError":"tbd","TaskName":"Divert Confirmation Down", "StateMachine":"" wms-tools-state-machine-divert-conf-down", " Lambda ":"wms-tools-lambda-divert-conf-down", "RequestType":"divert-conf-down"}','sysuser', 'sysuser' from app.cronactiontype cat, app.crontasks c where c.description = 'Divert Confirmation Down' and not exists (select 1 from app.cronaction c2 where c2.crontaskid = c.crontaskid) and cat.description = 'NONE'; | M12: DIVERT CONFIRMATION DOWN
A13: 73 | B13: =A13+1 -> 74 | C13: wms-tools-lambda-endpoint-queue-fail | D13: endpoint-queue-fail | E13: Endpoint Queue Failures | F13: tbd | G13: (select rt2.requesttypeid from app.requesttype rt2 where rt2.description = 'CRON Scheduling Dashboard') | H13: ="insert into app.requesttype(requesttypeid, approute, description, longdescription) select (select max(r.requesttypeid) from app.requesttype r) + 1 requesttypeid, " & A13 & ", '" & D13 & "', '" & D13 & "' where not exists (select 1 from app.requesttype r2 where r2.approute = " & A13 & " );" -> insert into app.requesttype(requesttypeid, approute, description, longdescription) select (select max(r.requesttypeid) from app.requesttype r) + 1 requesttypeid, 73, 'endpoint-queue-fail', 'endpoint-queue-fail' where not exists (select 1 from app.requesttype r2 where r2.approute = 73 ); | I13: ="insert into app.requesttype(requesttypeid, approute, description, longdescription) select (select max(r.requesttypeid) from app.requesttype r) + 1 requesttypeid, " & B13 & ", '" & D13 & " Interactive', '" & D13 & " Interactive' where not exists (select 1 from app.requesttype r2 where r2.approute = " & B13 & " );" -> insert into app.requesttype(requesttypeid, approute, description, longdescription) select (select max(r.requesttypeid) from app.requesttype r) + 1 requesttypeid, 74, 'endpoint-queue-fail Interactive', 'endpoint-queue-fail Interactive' where not exists (select 1 from app.requesttype r2 where r2.approute = 74 ); | J13: ="insert into app.statemachinerepo(statemachine, description, requesttypeid) select '" & F13 & "-' || rt.description" & ", '" & F13 & "-' || rt.description" & ", rt.requesttypeid from app.requesttype rt where rt.description = '" & D13 & "' and not exists (select 1 from app.statemachinerepo sr where sr.description = '" & F13 & "-" & D13 & "');" -> insert into app.statemachinerepo(statemachine, description, requesttypeid) select 'tbd-' || rt.description, 'tbd-' || rt.description, rt.requesttypeid from app.requesttype rt where rt.description = 'endpoint-queue-fail' and not exists (select 1 from app.statemachinerepo sr where sr.description = 'tbd-endpoint-queue-fail'); | K13: {="insert into app.cronaction (CronTaskId, CronActionTypeId, Payload, CreatedBy, LastUpdatedBy) select c.crontaskid, cat.CronActionTypeId,'{""EmailTextOnError"":""tbd"",""TaskName"":""" & E13 & """, ""StateMachine"":""" & IF(ISNUMBER(SEARCH("DB Alert", E)), "wms-tools-state-machine-db-alert", """ wms-tools-state-machine-" & D13 & "" ) & """, "" Lambda "":"" & C2 & "", ""RequestType"":""" & D13 &"""}','sysuser', 'sysuser' from app.cronactiontype cat, app.crontasks c where c.description = '" & E13 & "' and not exists (select 1 from app.cronaction c2 where c2.crontaskid = c.crontaskid) and cat.description = 'NONE';"} -> insert into app.cronaction (CronTaskId, CronActionTypeId, Payload, CreatedBy, LastUpdatedBy) select c.crontaskid, cat.CronActionTypeId,'{"EmailTextOnError":"tbd","TaskName":"Endpoint Queue Failures", "StateMachine":"" wms-tools-state-machine-endpoint-queue-fail", " Lambda ":" & C2 & ", "RequestType":"endpoint-queue-fail"}','sysuser', 'sysuser' from app.cronactiontype cat, app.crontasks c where c.description = 'Endpoint Queue Failures' and not exists (select 1 from app.cronaction c2 where c2.crontaskid = c.crontaskid) and cat.description = 'NONE'; | L13: ="insert into app.cronaction (CronTaskId, CronActionTypeId, Payload, CreatedBy, LastUpdatedBy) select c.crontaskid, cat.CronActionTypeId,'{""EmailTextOnError"":""tbd"",""TaskName"":""" & E13 & """, ""StateMachine"":""" & IF(ISNUMBER(SEARCH("DB Alert", E13)), "wms-tools-state-machine-db-alert", """ wms-tools-state-machine-" & D13 & "" ) & """, "" Lambda "":""" & C13 & """, ""RequestType"":""" & D13 &"""}','sysuser', 'sysuser' from app.cronactiontype cat, app.crontasks c where c.description = '" & E13 & "' and not exists (select 1 from app.cronaction c2 where c2.crontaskid = c.crontaskid) and cat.description = 'NONE';" -> insert into app.cronaction (CronTaskId, CronActionTypeId, Payload, CreatedBy, LastUpdatedBy) select c.crontaskid, cat.CronActionTypeId,'{"EmailTextOnError":"tbd","TaskName":"Endpoint Queue Failures", "StateMachine":"" wms-tools-state-machine-endpoint-queue-fail", " Lambda ":"wms-tools-lambda-endpoint-queue-fail", "RequestType":"endpoint-queue-fail"}','sysuser', 'sysuser' from app.cronactiontype cat, app.crontasks c where c.description = 'Endpoint Queue Failures' and not exists (select 1 from app.cronaction c2 where c2.crontaskid = c.crontaskid) and cat.description = 'NONE'; | M13: ENDPOINT QUEUE FAILURES
A14: 75 | B14: =A14+1 -> 76 | C14: wms-tools-lambda-endpoint-status | D14: endpoint-status | E14: Endpoint Status | F14: tbd | G14: (select rt2.requesttypeid from app.requesttype rt2 where rt2.description = 'CRON Scheduling Dashboard') | H14: ="insert into app.requesttype(requesttypeid, approute, description, longdescription) select (select max(r.requesttypeid) from app.requesttype r) + 1 requesttypeid, " & A14 & ", '" & D14 & "', '" & D14 & "' where not exists (select 1 from app.requesttype r2 where r2.approute = " & A14 & " );" -> insert into app.requesttype(requesttypeid, approute, description, longdescription) select (select max(r.requesttypeid) from app.requesttype r) + 1 requesttypeid, 75, 'endpoint-status', 'endpoint-status' where not exists (select 1 from app.requesttype r2 where r2.approute = 75 ); | I14: ="insert into app.requesttype(requesttypeid, approute, description, longdescription) select (select max(r.requesttypeid) from app.requesttype r) + 1 requesttypeid, " & B14 & ", '" & D14 & " Interactive', '" & D14 & " Interactive' where not exists (select 1 from app.requesttype r2 where r2.approute = " & B14 & " );" -> insert into app.requesttype(requesttypeid, approute, description, longdescription) select (select max(r.requesttypeid) from app.requesttype r) + 1 requesttypeid, 76, 'endpoint-status Interactive', 'endpoint-status Interactive' where not exists (select 1 from app.requesttype r2 where r2.approute = 76 ); | J14: ="insert into app.statemachinerepo(statemachine, description, requesttypeid) select '" & F14 & "-' || rt.description" & ", '" & F14 & "-' || rt.description" & ", rt.requesttypeid from app.requesttype rt where rt.description = '" & D14 & "' and not exists (select 1 from app.statemachinerepo sr where sr.description = '" & F14 & "-" & D14 & "');" -> insert into app.statemachinerepo(statemachine, description, requesttypeid) select 'tbd-' || rt.description, 'tbd-' || rt.description, rt.requesttypeid from app.requesttype rt where rt.description = 'endpoint-status' and not exists (select 1 from app.statemachinerepo sr where sr.description = 'tbd-endpoint-status'); | K14: {="insert into app.cronaction (CronTaskId, CronActionTypeId, Payload, CreatedBy, LastUpdatedBy) select c.crontaskid, cat.CronActionTypeId,'{""EmailTextOnError"":""tbd"",""TaskName"":""" & E14 & """, ""StateMachine"":""" & IF(ISNUMBER(SEARCH("DB Alert", E)), "wms-tools-state-machine-db-alert", """ wms-tools-state-machine-" & D14 & "" ) & """, "" Lambda "":"" & C2 & "", ""RequestType"":""" & D14 &"""}','sysuser', 'sysuser' from app.cronactiontype cat, app.crontasks c where c.description = '" & E14 & "' and not exists (select 1 from app.cronaction c2 where c2.crontaskid = c.crontaskid) and cat.description = 'NONE';"} -> insert into app.cronaction (CronTaskId, CronActionTypeId, Payload, CreatedBy, LastUpdatedBy) select c.crontaskid, cat.CronActionTypeId,'{"EmailTextOnError":"tbd","TaskName":"Endpoint Status", "StateMachine":"" wms-tools-state-machine-endpoint-status", " Lambda ":" & C2 & ", "RequestType":"endpoint-status"}','sysuser', 'sysuser' from app.cronactiontype cat, app.crontasks c where c.description = 'Endpoint Status' and not exists (select 1 from app.cronaction c2 where c2.crontaskid = c.crontaskid) and cat.description = 'NONE'; | L14: ="insert into app.cronaction (CronTaskId, CronActionTypeId, Payload, CreatedBy, LastUpdatedBy) select c.crontaskid, cat.CronActionTypeId,'{""EmailTextOnError"":""tbd"",""TaskName"":""" & E14 & """, ""StateMachine"":""" & IF(ISNUMBER(SEARCH("DB Alert", E14)), "wms-tools-state-machine-db-alert", """ wms-tools-state-machine-" & D14 & "" ) & """, "" Lambda "":""" & C14 & """, ""RequestType"":""" & D14 &"""}','sysuser', 'sysuser' from app.cronactiontype cat, app.crontasks c where c.description = '" & E14 & "' and not exists (select 1 from app.cronaction c2 where c2.crontaskid = c.crontaskid) and cat.description = 'NONE';" -> insert into app.cronaction (CronTaskId, CronActionTypeId, Payload, CreatedBy, LastUpdatedBy) select c.crontaskid, cat.CronActionTypeId,'{"EmailTextOnError":"tbd","TaskName":"Endpoint Status", "StateMachine":"" wms-tools-state-machine-endpoint-status", " Lambda ":"wms-tools-lambda-endpoint-status", "RequestType":"endpoint-status"}','sysuser', 'sysuser' from app.cronactiontype cat, app.crontasks c where c.description = 'Endpoint Status' and not exists (select 1 from app.cronaction c2 where c2.crontaskid = c.crontaskid) and cat.description = 'NONE'; | M14: ENDPOINT STATUS
