Workbook

Sheet Progress List
B2: SPLUNK DECOMISSIONING
B4: Function/Area/Tool | C4: Total Cases | D4: Unstarted Work | E4: % Incomplete | F4: In Design | G4: % in Design | H4: Being Developed | I4: & in Being Developed | J4: Deployed | K4: % Deployed | L4: Comments/Updates | M4: Priotity
B5: Application Parameter Tool | C5: =COUNTIFS('Combination Splunk Activities'!$H:$H,"Application Parameter Tools") -> 13 | D5: =COUNTIFS('Combination Splunk Activities'!$H:$H,"Application Parameter Tools",'Combination Splunk Activities'!$K:$K,"Unstarted Work") -> 0 | E5: =D5/C5 -> 0 | F5: =COUNTIFS('Combination Splunk Activities'!$H:$H,"Application Parameter Tools",'Combination Splunk Activities'!$K:$K,"In Design") -> 0 | G5: =F5/C5 -> 0 | H5: =COUNTIFS('Combination Splunk Activities'!$H:$H,"Application Parameter Tools",'Combination Splunk Activities'!$K:$K,"Being Developed") -> 0 | I5: =H5/C5 -> 0 | J5: =COUNTIFS('Combination Splunk Activities'!$H:$H,"Application Parameter Tools",'Combination Splunk Activities'!$K:$K,"Deployed") -> 12 | K5: =(J5/C5) -> 0.92307692 | L5: 🔹 Application Parameter Tool - PIX TRX - 9/26/25 Update Development: Completed QA: Completed Current Phase: Business Validation - 11/6/25 Application Parameter Tool is Deployed Completed | M5: Completed
B6: MAWM Scheduled Script Dashboard for API's | C6: =COUNTIFS('Combination Splunk Activities'!H:H,"MAWM Scheduled Script Dashboard for API's",'Combination Splunk Activities'!B:B,"Yes") -> 11 | D6: =COUNTIFS('Combination Splunk Activities'!$H:$H,"MAWM Scheduled Script Dashboard for API's",'Combination Splunk Activities'!$K:$K,"Unstarted Work") -> 0 | E6: =D6/C6 -> 0 | F6: =COUNTIFS('Combination Splunk Activities'!$H:$H,"MAWM Scheduled Script Dashboard for API's",'Combination Splunk Activities'!$K:$K,"In Design") -> 0 | G6: =F6/C6 -> 0 | H6: =COUNTIFS('Combination Splunk Activities'!$H:$H,"MAWM Scheduled Script Dashboard for API's",'Combination Splunk Activities'!$K:$K,"Being Developed") -> 10 | I6: =H6/C6 -> 0.90909091 | J6: =COUNTIFS('Combination Splunk Activities'!$H:$H,"MAWM Scheduled Script Dashboard for API's",'Combination Splunk Activities'!$K:$K,"Deployed") -> 0 | K6: =(J6/C6) -> 0 | L6: 🔹 Scheduled Script Dashboard – Oddball SKU - 9/26/25 Use Case: CS15 - MAWM Scheduled Script Dashboard for APIs Development & Integration: In Progress - 11/6/2025 Scheduled Script tool in still In Progress in this sprint. Sprint ends in three weeks - 12/9/25 Completed but in business testing right now. This will be deployed in January due to the Blackout period. Two are built and there are eight left to build. - 1/6/2026 Ready to deploy to production for a few of the Scripts. Adding a Script for MATM that needed for go live next month. Next Steps: Deploy to Production, use a couple of the newly created Scheulded Scripts, shut them down in Splunk - 1/20/2026 Oddball SKU, waiting on the cloud deployment to production so this can begin running in production. Working on the TMS Scheulded script, have a call today to go through it with Michael Dubose today. This is being targeted for the next sprint. Going to look into the IREC after the TMS Scheulded Script Deployment. - 2/3/2026 Oddball script is completed and ready to go in WMS Tools. We are at the point where we can turn it off in Splunk and turn it on and have it run from the WMS Tool. TMS script for RNDC Level ORG is ready to test in Development. Michael & Thomas can run the test tomorrow to make sure it is working. | M6: 2
B7: New BI Tool/ Lambda Function - Will Call Alert | C7: =COUNTIFS('Combination Splunk Activities'!$H:$H,"New BI Tool/ Lambda Function") -> 1 | D7: =COUNTIFS('Combination Splunk Activities'!$H:$H,"New BI Tool/ Lambda Function",'Combination Splunk Activities'!$K:$K,"Unstarted Work") -> 0 | E7: =D7/C7 -> 0 | F7: =COUNTIFS('Combination Splunk Activities'!$H:$H,"New BI Tool/ Lambda Function",'Combination Splunk Activities'!$K:$K,"In Design") -> 0 | G7: =F7/C7 -> 0 | H7: =COUNTIFS('Combination Splunk Activities'!$H:$H,"New BI Tool/ Lambda Function",'Combination Splunk Activities'!$K:$K,"Being Developed") -> 1 | I7: =H7/C7 -> 1 | J7: =COUNTIFS('Combination Splunk Activities'!$H:$H,"New BI Tool/ Lambda Function",'Combination Splunk Activities'!$K:$K,"Deployed") -> 0 | K7: =(J7/C7) -> 0 | L7: 🔹 Will Call – Email Alerts - 9/26/25 Update Status: To be started after CS15 - MAWM Scheduled Script Dashboard for APIs use case is completed - 12/9/25 Decmossiong of the Server(2016), so we will need to priortize this case over the Alerting Dashboard Case. This is due to us needing to get off of the WMS and close the California. Current Note: Smooth planning, Get use case ready - 1/6/26 This is in Progress, althought it's being tracked separelty, it's going to be part of the Scheulded Scripts Dashboard. - 1/20/2026 Working on the WIll Call alert, which is still in development, hoping to put it into testing this week. - 2/3/2026 They are working on the email structure, which is HTML, which is closer to hwat we have currently, we decided against a PDF report. This will be in the development environment before the end of the week. The email structure to be used by the WIll Call alert and all of the other alerts is still being finalized, this is what will be used by all alerts going forward. | M7: 1
B8: Splunk Alerts(SQL/API Alerts) - WMS Tools Alerting Dashboard | C8: =COUNTIFS('Splunk Alerts'!$A$3:A123,"<>") -> 121 | D8: =COUNTIFS('Splunk Alerts'!$A:$A,"<>",'Splunk Alerts'!$I:$I,"Unstarted Work") -> 0 | E8: =D8/C8 -> 0 | F8: =COUNTIFS('Splunk Alerts'!$A:$A,"<>",'Splunk Alerts'!$I:$I,"In Design") -> 121 | G8: =F8/C8 -> 1 | H8: =COUNTIFS('Splunk Alerts'!$A:$A,"<>",'Splunk Alerts'!$I:$I,"Being Deveolped") -> 0 | I8: =H8/C8 -> 0 | J8: =COUNTIFS('Splunk Alerts'!$A:$A,"<>",'Splunk Alerts'!$I:$I,"Deployed") -> 0 | K8: =(J8/C8) -> 0 | L8: 🔹 WMS Tools Alerting Dashboard - 9/26/25 Kim & Memory to Meet with Camir next week to understand the POC that he built the first time around a year ago. - 11/6/25 Plan is to build this functionality into WMS Tools vs. Using Power BI/Power Automate. Kinsy & Thomas will start to work on this after the Scheudled Script Tool is Deployed to Production. - 12/9/25 Started Development. Using Inventory Adjustment PIX Missing Reason Code as a POC to start eh development. Time Frame : Kinsy to do some analysis to see how long it will take to complete the last three tools to get off of Splunk completely. - 1/6/26 Final list of Alerts is being complied. A few meetings have been had, we have close to the final list. Kinsy is working on an estimate of how long it will take to develop. - 1/20/2026 We have final list. We are goignt o scheuld a meeting to come up with a priority and that way development can begin on this section. - 2/3/2026 They are working on the embeded HTML table that will be used for all alerts, but they are starting with the Will Call alerts. Once it's complete we can move from the Will Call alert they will move on to the other alerting. | M8: 3
B10: Function/Area/Tool | C10: Total Cases | D10: Unstarted | E10: % Incomplete | F10: In Design | G10: % in Design | H10: Being Developed | I10: & in Being Developed | J10: Deployed | K10: % Deployed
B11: All | C11: =SUM(C5:C8) -> 146 | D11: =SUM(D5:D8) -> 0 | E11: =D11/C11 -> 0 | F11: =SUM(F5:F8) -> 121 | G11: =F11/C11 -> 0.82876712 | H11: =SUM(H5:H8) -> 11 | I11: =H11/C11 -> 0.075342466 | J11: =SUM(J5:J8) -> 12 | K11: =J11/C11 -> 0.082191781
B15: Power BI Dashboards
B17: Dashboard/Report/Tool | C17: MAWM Replicated SQL Complete? | D17: SQL Rewritten in Snowflake? | E17: Comments | G17: Data Model Created? | H17: Comments | J17: Power BI Dashboard Created? | K17: Comments
B18: Workload Summary | C18: Complete | D18: Complete | E18: Need to Open a Ticket with W&H, to double check the validy of their data. | G18: Complete | H18: I believe Mark has the initial Model created. There is a data issue on how this data is pulled into snowflake, and it has to do with a date field that is being populated. | J18: In Progress | K18: Chad to provide some assistance with writing a Power BI report for this.
B19: Inventory Tracking Dashboard | C19: Complete | D19: Complete | E19: Data Team had Snowflake SQL. | G19: In Progress | H19: No started yet | J19: Incomplete
B20: Inbound Receiving Volume Dashboard | C20: Complete | D20: Complete | E20: Updates being made to MAWM Replicated SQL | G20: Incomplete | H20: Not started yet | J20: Incomplete
B21: Inbound Transfer Volume Dashboard | C21: Complete | D21: Complete | E21: Updates being made to MAWM Replicated SQL | G21: Incomplete | H21: Not started yet | J21: Incomplete
B22: Demand Order Outbound Volume Dashboard | C22: Complete | D22: Complete | E22: Updates being made to MAWM Replicated SQL | G22: Incomplete | H22: Not started yet | J22: Incomplete
B23: Slotting Dashboard | C23: Complete | D23: Complete | E23: Data Team had Snowflake SQL. | G23: Complete | H23: From what I understand this is in progress. - This is completed, ready to write the Power BI report. | J23: Incomplete | K23: Chad to provide some assistance with writing a Power BI report for this.
B24: Cycle Count Dashboard | C24: Complete | D24: Complete | E24: Updates being made to MAWM Replicated SQL | G24: Incomplete | H24: Not started yet | J24: Incomplete
B25: Returns Dashboard | C25: In Progress | D25: Incomplete | E25: This has not been started yet. Will be upon completion of the Inbound Dashboards. | G25: Incomplete | H25: Not started yet | J25: Incomplete
B26: Activity Tracking Warehouse Report | C26: In Progress | D26: Incomplete | E26: Requested the Current SQL that Agilitics wrote, need to review. | G26: Incomplete | H26: Not started yet | J26: Incomplete
B27: Foecast Data SQL's | C27: Completed | D27: Completed | E27: Bricz currently working on Snowflake SQL. | G27: Incomplete | H27: Not started yet | J27: Incomplete

Sheet Sheet1
D11: Power BI Dashboards
D13: Dashboard/Report/Tool | E13: MAWM Replicated SQL Complete? | F13: SQL Rewritten in Snowflake? | G13: Data Model Created? | H13: Power BI Dashboard Created?
D14: Workload Summary | E14: Complete | F14: Complete | G14: Complete | H14: In Progress
D15: Inventory Tracking Dashboard | E15: Complete | F15: Complete | G15: In Progress | H15: Incomplete
D16: Inbound Receiving Volume Dashboard | E16: Complete | F16: Complete | G16: Incomplete | H16: Incomplete
D17: Inbound Transfer Volume Dashboard | E17: Complete | F17: Complete | G17: Incomplete | H17: Incomplete
D18: Demand Order Outbound Volume Dashboard | E18: Complete | F18: In Progress | G18: Incomplete | H18: Incomplete
D19: Slotting Dashboard | E19: Complete | F19: Complete | G19: Complete | H19: Incomplete
D20: Cycle Count Dashboard | E20: In Progress | F20: Incomplete | G20: Incomplete | H20: Incomplete
D21: Returns Dashboard | E21: In Progress | F21: Incomplete | G21: Incomplete | H21: Incomplete
D22: Activity Tracking Warehouse Report | E22: In Progress | F22: Incomplete | G22: Incomplete | H22: Incomplete
D23: Foecast Data SQL's | E23: Completed | F23: Completed | G23: Incomplete | H23: Incomplete

Sheet Final_List-Alerts
A1: Tasks | B1: Priority | C1: ERP/WMS | D1: Needed | E1: Type | F1: Database | G1: Assigned To | H1: Email | I1: Comments | J1: Stakeholder | K1: Email Template | L1: DEV | M1: QA | N1: Production
A2: ALLOCATED LPNS WITH NO OPEN TASK DETAILS API FAILURE | B2: Low | C2: WMS | D2: Yes | E2: API | F2: MAWM | G2: Kinsy | I2: splunk/manhattan_active/ASH/alloclpns_noopntskdtls
A3: ALPHA ASN ERROR | B3: Medium | C3: ERP | D3: Yes | E3: FTP File Search | F3: ALPHA | G3: Thomas | I3: ALPHA ASN ERROR & ASW ASN ERROR are same index = main host="misssplunksh01.corp.rndc-usa.com" sourcetype=alphaasn | eval file_date=strftime(now(), "%Y-%m-%d") | eval mySource="/splunk/FTP/Alpha/asn/abq_asnhdr_" + file_date + ".txt" | where match(source, mySource) | eval ASN=substr(_raw,1,20), STATUS=substr(substr(_raw,20,21),1,2) | eval House="ABQ" | eval Error_Description=case(STATUS == " 1", "Header Error", STATUS ==" 2", "Line Item Error") | where STATUS in (" 1"," 2") | rename STATUS as "Error Status", Error_Description as "Error Description" | table House, ASN, "Error Status", "Error Description", _time This Splunk search pulls today’s ABQ ASN header file, extracts the ASN number and error status from fixed positions in the file, and labels the warehouse as ABQ. It then filters only error records (Status 1 = Header Error, Status 2 = Line Item Error) and displays the results with timestamps for reporting. The final result will send via email formatted as table using HTML embedded in the email | J3: Jacod Reed or Dax Solomon
A4: ALPHA OPEN ADJUSTMENTS > 35DAYS | B4: 11 | C4: ERP | D4: Yes | E4: FTP File Search | F4: ALPHA | G4: Thomas | I4: sourcetype=alpha_adj | regex "\s\s\s\s\s\s\s\s\s\s\s\s\s\s\s\s\s\s\s\s\s\s\s\s\s\s\s\s\s\s\s\s\s\s\s\s\s\s\s\s\s\s\s\s\s\s\s\s\s\s\s\s\s\s\s[1]" | eval file_date=strftime(now(), "%Y-%m-%d")| eval mySource="/splunk/FTP/Alpha/adj/atl_adjtrx_" + file_date + ".txt" | where match(source, mySource) | table source,Item, REASON, _time | rex field=source mode=sed "s/\/splunk\/FTP\/Alpha\/adj\/atl_*(.+)/ATL/g" | rename source AS "House" | sort House |dedup Item This search filters **today’s ATL Alpha adjustment file** to find records with a specific fixed-position pattern (ending in status **1**), indicating a certain type of adjustment/error. It then formats the output to show **House (ATL), Item, Reason, and Time**, removes duplicates by Item, and sorts the results for clean reporting. The final result will send via email formatted as table using HTML embedded in the email
A5: ALPHA OPEN/ERROR ASN | B5: 12 | C5: ERP | D5: Yes | E5: FTP File Search | F5: ALPHA | G5: Thomas | I5: sourcetype=alphaasn White!=9 latest=-2d@d earliest=0 | eval file_date=strftime(now(), "%Y-%m-%d") | eval mySource="/splunk/FTP/Alpha/asn/abq_asnhdr_" + file_date + ".txt" | where match(source, mySource)| search | eval Date=_time | convert timeformat="%Y-%m-%d" ctime(Date) | table source,ASN,White,Date | rex field=source mode=sed "s/\/splunk\/FTP\/Alpha\/asn\/abq_*(.+)/ABQ/g" | rex field=White mode=sed "s/[0]/Open_ASN/g" | rex field=White mode=sed "s/[1]/Header_Values_Errors/g" | rex field=White mode=sed "s/[2]/Line_Item_Errors/g" | rename source AS "House", White AS "Status" | sort House ----- This search pulls today’s ABQ ASN header file and filters records where the ASN status is not “9,” then formats the date for reporting. It converts numeric status codes into readable error descriptions (Open, Header Errors, Line Item Errors) and displays the results by House, ASN, Status, and Date.
A6: ALPHA OPEN RETURNS | B6: Medium | C6: ERP | D6: Yes | E6: FTP File Search | F6: ALPHA | G6: Thomas | I6: index = alpharet punct=__________________________________________________ | eval file_date=strftime(now(), "%Y-%m-%d") | eval mySource="/splunk/FTP/Alpha/ret/atl_retlpn_" + file_date + ".txt" | where match(source, mySource)| search This Splunk search looks in the alpharet index for events whose source file name matches today’s ATL retail LPN file (based on the current date). It then filters the results to only those matching that specific file path and applies any additional search conditions. The final result will send via email formatted as table using HTML embedded in the email
A7: ASN S WITH NO ASN LEVEL VERIFICATION > 5DAYS | B7: Low | C7: Middleware | D7: Yes | E7: DBQuery | F7: Mulesoft | G7: Thomas | I7: ABQ_MIDDLE_PROD | J7: Mikaelo or Shrini
A8: ASW ASN ERROR | B8: Medium | C8: ERP | D8: Yes | E8: FTP File Search | F8: ASW | G8: Thomas | I8: sourcetype = asn_error_csv | eval file_date=strftime(now(), "%Y_%m_%d") | eval mySource="/splunk/FTP/ASW/ASN_Errors_" + file_date + ".csv" | where match(source, mySource) | table AHZMSROM AHZMASNN _time | rename AHZMSROM AS "HOUSE" AHZMASNN AS "ASN" -----This Splunk search finds today’s ASN error CSV file and filters events to only that specific file path. It then displays the HOUSE, ASN, and time fields in a clean table format. The final result will send via email formatted as table using HTML embedded in the email | J8: Harvey Goldstein, Robert curl
A9: DIVERT CONFIRMATION DOWN | B9: High | C9: WMS | D9: Yes | E9: API | G9: Thomas | I9: /splunk/manhattan_active/ALLMAWM/au02_divert_confirm_source_destination_down
A10: DUPLICATE PIX S IN MIDDLEWARE WMS | B10: High | C10: Middleware | D10: Yes | E10: DBQuery | F10: Mulesoft | G10: Thomas | I10: Combine DUPLICATE PIX S IN MIDDLEWARE WMS " & DUPLICATE PIX S IN SOA WMS name as Mulesoft - refer the code in SOA
A11: DUPLICATE PIX S IN SOA WMS | D11: No | E11: DBQuery | F11: My SQL | G11: Kinsy | I11: 10.248.248.195 - MAPRD_NEW
A12: DUPLICATE SHIP CONFIRM | B12: High | C12: Middleware | D12: Yes | E12: DBQuery | F12: Oracle/Mulesoft | G12: Kinsy | I12: MAWM_SOA_PRD - jdbc:oracle:thin:@at4ex01-scan1.corp.rndc-usa.com:1521/pwmsods_svc1
A13: ENDPOINT QUEUE FAILURES | B13: Low | C13: WMS | D13: Yes | E13: API | G13: Thomas | I13: /splunk/manhattan_active/ABQ/failure_count/
A14: ENDPOINT STATUS | B14: Medium | C14: WMS | D14: Yes | E14: API | G14: Thomas | I14: /splunk/manhattan_active/ARK/endpoint_status/
A15: ILPNS WITH MISSING PHYSICALENTITYCODEID | B15: Low | C15: WMS | D15: Yes | E15: DBQuery | F15: My SQL | G15: Kinsy | I15: 10.248.248.195 - MAPRD_NEW
A16: ILPNS WITH NEGATIVE ALLOCATED QUANTITY API FAILURE | B16: Low | C16: WMS | D16: Yes | E16: API | G16: Kinsy
A17: INVENTORY ADJUSTMENT PIX MISSING REASON CODE | B17: High | C17: WMS | D17: Yes | E17: DBQuery | F17: My SQL | G17: Kinsy
A18: INVENTORY SYNC SCHEDULE API FAILED | B18: 13 | C18: WMS | D18: Yes | E18: API | G18: Kinsy | I18: Same inventory_sync_schedule - calling script /splunk/manhattan_active/ABQ/inventory_sync_schedule/inventory_sync_schedule_check_status.csv | K18: The alert condition for '$name$' was triggered. Description: Manhattan case 7115910 is open for this. ***MSP TO CLEAN UP*** Steps to Correct:Run the SQL update(s) in the Middleware DB for each house. Commit these updates after running. | L18: 5 | M18: 2 | N18: 1
A19: ITEM IMAGE URL FAILURE | B19: 17 | C19: WMS | D19: Yes | E19: API | G19: Kinsy | I19: FTP file path to get the image list
A20: ITEM LEVEL RECEIPTS WITH 0 QUANTITY | B20: High | C20: WMS | D20: Yes | E20: DBQuery | F20: My SQL | G20: Kinsy | I20: 10.248.248.195 - MAPRD_NEW
A21: LIA RECORDS WITH PACK UOM TYPE POPULATED | B21: Low | C21: WMS | D21: Yes | E21: DBQuery | F21: My SQL | G21: Kinsy | K21: The alert condition for '$name$' was triggered. ***MSP TO CLEAN UP***
A22: LOCATION POSITION > STREET LENGTH | B22: Low | C22: WMS/LMS | D22: Yes | E22: DBQuery | F22: My SQL | G22: Kinsy | I22: 10.248.248.195 - MAPRD_NEW ; email to lmteam@rndc-usa.com
A23: LOCATION REBUILD FAILURE | B23: Low | C23: WMS | D23: Yes | E23: API | G23: Kinsy | I23: splunk/manhattan_active/ABQ/location_rebuild. Only API call and no select query from mysql
A24: LOCATIONS W/ INVENTORY FOR ITEMS NOT ASSIGNED | B24: Low | C24: WMS | D24: Yes | E24: DBQuery | F24: My SQL | G24: Kinsy | I24: 10.248.248.195 - MAPRD_NEW
A25: LONG RUNNING OR ABORTED WAVES | B25: High | C25: WMS | D25: Yes | E25: DBQuery | F25: My SQL | G25: Kinsy | I25: 10.248.248.195 - MAPRD_NEW
A26: LPNS WITH CONSUMED/CANCELLED ALLOCATED QUANTITY API FAILURE | B26: Meium | C26: WMS | D26: Yes | E26: API | G26: Kinsy | I26: execute select sql and call MA API Endpoint. /splunk/manhattan_active/ABQ/lpn_consumed_cancel_allocation
A27: MISSING ITEM LEVEL VERIFICATION PIX | B27: High | C27: Middleware | D27: Yes | E27: DBQuery | F27: Oracle/Mulesoft | G27: Kinsy | I27: MAWM_SOA_PRD - jdbc:oracle:thin:@at4ex01-scan1.corp.rndc-usa.com:1521/pwmsods_svc1
A28: MONTHLY SLOTTING DASHBOARD | C28: WMS | D28: No | E28: DBQuery | F28: My SQL | G28: Kinsy | I28: Query runs in python script and create csv file. /splunk/manhattan_active/ALLMAWM/monthly_slotting_dashboard
A29: OPEN PICK PACK TASK DETAILS API FAILURE | B29: Low | C29: WMS | D29: Yes | E29: API | G29: Kinsy | I29: Run select query and update API endpoint. /splunk/manhattan_active/ABQ/tskdtls_comp_openpickpacktskdtls
A30: ASW OPEN RETURNS | B30: Medium | C30: ERP | D30: Yes | E30: FTP File Search | F30: ASW | G30: Kinsy | I30: Returns House and Open Return values from today’s Cust_Rtn_Pallets CSV file only, with the event date displayed.. Searching FTP file path /splunk/FTP/ASW/Cust_Rtn_Pallets_* The final result will send via email formatted as table using PDF attached in the email
A31: OPEN TASK API FAILURE | B31: Low | C31: WMS | D31: Yes | E31: API | G31: Kinsy | I31: Run select query and update API endpoint. - /splunk/manhattan_active/LUB/open_task
A32: OPEN TASK DETAILS API FAILURE | B32: Low | C32: WMS | D32: Yes | E32: API | G32: Kinsy | I32: Run select query and update API endpoint. - /splunk/manhattan_active/ATL/open_task_details
A33: ORDERS NOT PROCESS IN HOST > 15 MINUTES | B33: 4 | C33: Middleware | D33: Yes | E33: DBQuery | F33: Oracle/Mulesoft | G33: Kinsy | I33: | dbxquery query="SELECT warehouse, invoice_no, item_no, ship_qty, prc_status, created_dttm, messageid FROM ark_wmsods.ship_confirm WHERE prc_status = 10 AND created_dttm < sysdate - 60/1440 ORDER BY created_dttm desc" connection="MAWM_SOA_PRD"
A34: ORDERS STUCK IN CREATED STATUS > 15 MINUTES | B34: 5 | C34: WMS | D34: Yes | E34: DBQuery | F34: My SQL | G34: Kinsy | I34: 10.248.248.195 - MAPRD_NEW
A35: ELP ASW -PENDING SHIPMENT QUANTITIES > 1 WEEK | B35: Low | C35: Host | D35: Yes | E35: FTP File Search | F35: ASW | G35: Kinsy | I35: To retrieve and display today’s Pending Open Shipments records for SISROM = EL1 by filtering events to today’s CSV file and presenting key shipment fields in a readable format. (/splunk/FTP/ASW/Pending_Shipments_Open_" + file_date + ".csv") The final result will send via email formatted as table using PDF attached in the email
A36: PICK LOCATIONS WITH NEGATIVE TBF API FAILURE | B36: High | C36: WMS | D36: Yes | E36: API | G36: Kinsy | I36: Run select query and update API endpoint../splunk/manhattan_active/ABQ/pick_loc_negative_tbf
A37: PICK LOCATIONS WITH TBF QUANTITY AND NO OPEN TASK DETAILS API FAILURE | B37: High | C37: WMS | D37: Yes | E37: API | G37: Kinsy | I37: /splunk/manhattan_active/ABQ/pick_loc_tbf_qty_taskdtls
A38: PUTAWAY TASK DETAILS API FAILURE | B38: Medium | C38: WMS | D38: Yes | E38: API | G38: Kinsy | I38: /splunk/manhattan_active/ABQ/ptwytskdtlsopen_nottiedtskhdr
A39: RECOUP SORTING UPDATE API FAILURE | B39: Medium | C39: WMS | D39: Yes | E39: API | G39: Kinsy | I39: /splunk/manhattan_active/DFB/recoup_sort_update_lpn
A40: ROUTED ORDERS CANCELLED | B40: High | C40: WMS | D40: Yes | E40: DBQuery | F40: My SQL | G40: Kinsy | I40: 10.248.248.195 - MAPRD_NEW
...

Sheet api.alert
A2: No | B2: ='Final_List-Alerts'!A1 -> Tasks | C2: sorting | D2: Priority | E2: splunk search content | F2: python + sql + shell script | G2: FTP | H2: TXT | I2: csv | J2: PY | K2: eval | L2: SQL | M2: MAPI | N2: dev status | O2: Notes | P2: csv file name
A3: 1 | B3: ='Final_List-Alerts'!A58 -> WILL CALL | C3: =D3 -> 1 | D3: ='Final_List-Alerts'!B58 -> 1 | J3: 1 | M3: 1 | N3: pending dev
A4: =A3+1 -> 2 | B4: ='Final_List-Alerts'!A67 -> AU01 FAILURE [URGENT] | C4: =D4 -> 2 | D4: ='Final_List-Alerts'!B67 -> 2 | E4: source="/splunk/manhattan_active/ABQ/failure_count_10min/message_failure_count_list.csv" host="misssplunksh01.corp.rndc-usa.com" index="ymc_dev_wms" Endpoint_Name=WOR_DEI_AllocationDownloadMsg |rename Endpoint_Name as Name, Error_Count as Count | table Name Count | F4: /splunk/manhattan_active/ABQ/message_count.py and /dmui-facade/api/dmui-facade/metric/search | J4: 1 | M4: 1
A5: =A4+1 -> 3 | B5: ='Final_List-Alerts'!A84 -> ATL In Transit RMA ASNs > 30 Days Splunk Alert | C5: =D5 -> 3 | D5: ='Final_List-Alerts'!B84 -> 3 | E5: source="/splunk/manhattan_active/ALLMAWM/hawaii-in-transit-rma-asns/Logs/hawaii-in-transit-rma-asns-HAW.csv" host="misssplunksh01.corp.rndc-usa.com" index="ymc_dev_wms" sourcetype="csv" | Table "ASN Id", Status | F5: "/splunk/manhattan_active/ALLMAWM | I5: 1 | J5: 1 | M5: 1 | O5: ="questions at " & misc.questions!A3 & "." & misc.questions!B3& " org id haw, kap, kau, mau, oah " -> questions at hawaii-in-transit-rma-asns.do we need to do both stage and prod org id haw, kap, kau, mau, oah | P5: =MID(E5, LEN("source=""/splunk/manhattan_active/"), FIND("csv", E5) - LEN("source=""/splunk/manhattan_active/")+3) -> /ALLMAWM/hawaii-in-transit-rma-asns/Logs/hawaii-in-transit-rma-asns-HAW.csv
A6: =A5+1 -> 4 | B6: ='Final_List-Alerts'!A18 -> INVENTORY SYNC SCHEDULE API FAILED | C6: =D6 -> 13 | D6: ='Final_List-Alerts'!B18 -> 13 | E6: source="/splunk/manhattan_active/ABQ/inventory_sync_schedule/inventory_sync_schedule_check_status.csv" host="misssplunksh01.corp.rndc-usa.com" index="ymc_dev_wms" "Inventory sync schedule API Failed" |rename "Inventory sync schedule API Status" as Status | table Status, _time | I6: 1 | J6: 1 | M6: 1 | P6: =MID(E6, LEN("source=""/splunk/manhattan_active/"), FIND("csv", E6) - LEN("source=""/splunk/manhattan_active/")+3) -> /ABQ/inventory_sync_schedule/inventory_sync_schedule_check_status.csv
A7: =A6+1 -> 5 | B7: ='Final_List-Alerts'!A62 -> Mark Dynamic Case Pick (dynamic_casepick_liquor) | C7: =D7 -> 14 | D7: ='Final_List-Alerts'!B62 -> 14
A8: =A7+1 -> 6 | B8: ='Final_List-Alerts'!A63 -> Mark Dynamic Wine (dynamic_casepick_wine) | C8: =D8 -> 15 | D8: ='Final_List-Alerts'!B63 -> 15
A9: =A8+1 -> 7 | B9: ='Final_List-Alerts'!A19 -> ITEM IMAGE URL FAILURE | C9: =D9 -> 17 | D9: ='Final_List-Alerts'!B19 -> 17 | E9: source="/splunk/manhattan_active/ABQ/item_image_url/itemURL_bulk_import_check_status.csv" host="misssplunksh01.corp.rndc-usa.com" index="ymc_dev_wms" sourcetype="csv" "ItemURL Bulk Import API Failed" | rename "Item URL Bulk Import API Status" as Status | table Status, _time | G9: 1 | I9: 1 | J9: 1 | M9: 1 | P9: =MID(E9, LEN("source=""/splunk/manhattan_active/"), FIND("csv", E9) - LEN("source=""/splunk/manhattan_active/")+3) -> /ABQ/item_image_url/itemURL_bulk_import_check_status.csv
A10: =A9+1 -> 8 | B10: ='Final_List-Alerts'!A9 -> DIVERT CONFIRMATION DOWN | C10: 100 | D10: ='Final_List-Alerts'!B9 -> High | E10: source="/splunk/manhattan_active/ALLMAWM/au02_divert_confirm_source_destination_down/au02_divert_confirm_source_destination_down_Prod.csv" host="misssplunksh01.corp.rndc-usa.com" index="ymc_dev_wms" sourcetype="csv" |rename PROFILEID as Profile_ID, ENDPOINTID as Endpoint_ID | table Profile_ID Endpoint_ID | I10: 1 | J10: 1 | M10: 1 | P10: =MID(E10, LEN("source=""/splunk/manhattan_active/"), FIND("csv", E10) - LEN("source=""/splunk/manhattan_active/")+3) -> /ALLMAWM/au02_divert_confirm_source_destination_down/au02_divert_confirm_source_destination_down_Prod.csv
A11: =A10+1 -> 9 | B11: ='Final_List-Alerts'!A36 -> PICK LOCATIONS WITH NEGATIVE TBF API FAILURE | C11: 100 | D11: ='Final_List-Alerts'!B36 -> High | E11: source="/splunk/manhattan_active/ABQ/pick_loc_negative_tbf/pick_loc_negative_tbf_status.csv" host="misssplunksh01.corp.rndc-usa.com" index="ymc_dev_wms" sourcetype="csv" "Pick Locations With Negative TBF API Failed" | rename "Pick Locations With Negative TBF API Status" as Status | table Status, _time | I11: 1 | J11: 1 | L11: 1 | M11: 1 | P11: =MID(E11, LEN("source=""/splunk/manhattan_active/"), FIND("csv", E11) - LEN("source=""/splunk/manhattan_active/")+3) -> /ABQ/pick_loc_negative_tbf/pick_loc_negative_tbf_status.csv
A12: =A11+1 -> 10 | B12: ='Final_List-Alerts'!A37 -> PICK LOCATIONS WITH TBF QUANTITY AND NO OPEN TASK DETAILS API FAILURE | C12: 100 | D12: ='Final_List-Alerts'!B37 -> High | E12: source="/splunk/manhattan_active/ABQ/pick_loc_tbf_qty_taskdtls/pick_loc_tbf_qty_taskdtls_status.csv" host="misssplunksh01.corp.rndc-usa.com" index="ymc_dev_wms" sourcetype="csv" "Pick Location TBF Qty Open Task Details API Failed" | rename "Pick Location TBF Qty Open Task Details API Status" as Status | table Status, _time | I12: 1 | J12: 1 | L12: 1 | M12: 1 | P12: =MID(E12, LEN("source=""/splunk/manhattan_active/"), FIND("csv", E12) - LEN("source=""/splunk/manhattan_active/")+3) -> /ABQ/pick_loc_tbf_qty_taskdtls/pick_loc_tbf_qty_taskdtls_status.csv
A13: =A12+1 -> 11 | B13: ='Final_List-Alerts'!A43 -> SLOTTING ITEM DEMAND PACK FAILURE | C13: 100 | D13: ='Final_List-Alerts'!B43 -> High | E13: source="/splunk/manhattan_active/ABQ/slot_itemdemand_pack/slotitemdemand_pack_check_status.csv" host="misssplunksh01.corp.rndc-usa.com" index="ymc_dev_wms" sourcetype="csv" "Slotting Item Demand Pack Import API Failed" | rename "Slot Item Demand Pack Import API Status" as Status | table Status, _time | I13: 1 | J13: 1 | L13: 1 | M13: 1 | P13: =MID(E13, LEN("source=""/splunk/manhattan_active/"), FIND("csv", E13) - LEN("source=""/splunk/manhattan_active/")+3) -> /ABQ/slot_itemdemand_pack/slotitemdemand_pack_check_status.csv
A14: =A13+1 -> 12 | B14: ='Final_List-Alerts'!A44 -> SLOTTING ITEM DEMAND UNIT FAILURE | C14: 100 | D14: ='Final_List-Alerts'!B44 -> High | E14: source="/splunk/manhattan_active/ABQ/slot_itemdemand_unit/slotitemdemand_unit_check_status.csv" host="misssplunksh01.corp.rndc-usa.com" index="ymc_dev_wms" sourcetype="csv" "Slotting Item Demand Unit Import API Failed" | rename "Slot Item Demand Unit Import API Status" as Status | table Status, _time | I14: 1 | J14: 1 | L14: 1 | M14: 1 | P14: =MID(E14, LEN("source=""/splunk/manhattan_active/"), FIND("csv", E14) - LEN("source=""/splunk/manhattan_active/")+3) -> /ABQ/slot_itemdemand_unit/slotitemdemand_unit_check_status.csv
A15: =A14+1 -> 13 | B15: ='Final_List-Alerts'!A14 -> ENDPOINT STATUS | C15: 200 | D15: ='Final_List-Alerts'!B14 -> Medium | E15: source="/splunk/manhattan_active/AUB/endpoint_status/endpoint_status.csv" host="misssplunksh01.corp.rndc-usa.com" index="ymc_dev_wms" sourcetype="ma-endpoint_csv" "AU01_WaveDownload_Endpoint" OR "AU02_DivertConfirm_Endpoint" OR "AU02_PickComplete_Endpoint" OR "AU03_CartonComplete_Endpoint" OR AU02_PickComplete_AWPF_Endpoint OR AU03CompleteCartonEndpoint | where Status = "Stopped" | table Create_time Description Name Type Status | I15: 1 | J15: 1 | M15: 1 | P15: =MID(E15, LEN("source=""/splunk/manhattan_active/"), FIND("csv", E15) - LEN("source=""/splunk/manhattan_active/")+3) -> /AUB/endpoint_status/endpoint_status.csv
A16: =A15+1 -> 14 | B16: ='Final_List-Alerts'!A26 -> LPNS WITH CONSUMED/CANCELLED ALLOCATED QUANTITY API FAILURE | C16: 200 | D16: ='Final_List-Alerts'!B26 -> Meium | E16: source="/splunk/manhattan_active/ABQ/alloclpns_noopntskdtls/rebuild_lpn_status.csv" host="misssplunksh01.corp.rndc-usa.com" index="ymc_dev_wms" sourcetype="csv" "Rebuild LPNs API Failed" | rename "Rebuild LPNs Status" as Status | table Status, _time | I16: 1 | J16: 1 | L16: 1 | M16: 1 | P16: =MID(E16, LEN("source=""/splunk/manhattan_active/"), FIND("csv", E16) - LEN("source=""/splunk/manhattan_active/")+3) -> /ABQ/alloclpns_noopntskdtls/rebuild_lpn_status.csv
A17: =A16+1 -> 15 | B17: ='Final_List-Alerts'!A38 -> PUTAWAY TASK DETAILS API FAILURE | C17: 200 | D17: ='Final_List-Alerts'!B38 -> Medium | E17: source="/splunk/manhattan_active/ABQ/ptwytskdtlsopen_nottiedtskhdr/putaway_task_details_status.csv" host="misssplunksh01.corp.rndc-usa.com" index="ymc_dev_wms" sourcetype="csv" "Putaway Task Details API Failed" | rename "Putaway Task Details" as Status | table Status, _time | dedup Status | I17: 1 | J17: 1 | L17: 1 | M17: 1 | P17: =MID(E17, LEN("source=""/splunk/manhattan_active/"), FIND("csv", E17) - LEN("source=""/splunk/manhattan_active/")+3) -> /ABQ/ptwytskdtlsopen_nottiedtskhdr/putaway_task_details_status.csv
A18: =A17+1 -> 16 | B18: ='Final_List-Alerts'!A39 -> RECOUP SORTING UPDATE API FAILURE | C18: 200 | D18: ='Final_List-Alerts'!B39 -> Medium | E18: source="/splunk/manhattan_active/DFB/recoup_sort_update_lpn/update_lpn_status.csv" host="misssplunksh01.corp.rndc-usa.com" index="ymc_dev_wms" sourcetype="csv" "Update LPN Inventory API Failed" | rename "Update LPN Inventory API Status" as Status | table Status, _time | I18: 1 | J18: 1 | L18: 1 | M18: 1 | P18: =MID(E18, LEN("source=""/splunk/manhattan_active/"), FIND("csv", E18) - LEN("source=""/splunk/manhattan_active/")+3) -> /DFB/recoup_sort_update_lpn/update_lpn_status.csv
A19: =A18+1 -> 17 | B19: ='Final_List-Alerts'!A45 -> SLOTTING LIA DELETE PK RECORDS API FAILURE | C19: 200 | D19: ='Final_List-Alerts'!B45 -> Medium | E19: source="/splunk/manhattan_active/ABQ/slotting_lia_delete/slotting_lia_delete_status.csv" host="misssplunksh01.corp.rndc-usa.com" index="ymc_dev_wms" sourcetype="csv" "Slotting" | rename "Slotting Location PK Search API Status" as Status | table Status, _time | I19: 1 | J19: 1 | L19: 1 | M19: 1 | P19: =MID(E19, LEN("source=""/splunk/manhattan_active/"), FIND("csv", E19) - LEN("source=""/splunk/manhattan_active/")+3) -> /ABQ/slotting_lia_delete/slotting_lia_delete_status.csv
A20: =A19+1 -> 18 | B20: ='Final_List-Alerts'!A2 -> ALLOCATED LPNS WITH NO OPEN TASK DETAILS API FAILURE | C20: 300 | D20: ='Final_List-Alerts'!B2 -> Low | E20: source="/splunk/manhattan_active/ABQ/alloclpns_noopntskdtls/rebuild_lpn_status.csv" host="misssplunksh01.corp.rndc-usa.com" index="ymc_dev_wms" sourcetype="csv" "Rebuild LPNs API Failed" | rename "Rebuild LPNs Status" as Status | table Status, _time | F20: /splunk/manhattan_active/ABQ/alloclpns_noopntskdtls/alloclpns_noopntskdtls.py and alloclpns_noopntskdtls.sql | I20: 1 | J20: 1 | L20: 1 | P20: =MID(E20, LEN("source=""/splunk/manhattan_active/"), FIND("csv", E20) - LEN("source=""/splunk/manhattan_active/")+3) -> /ABQ/alloclpns_noopntskdtls/rebuild_lpn_status.csv
A21: =A20+1 -> 19 | B21: ='Final_List-Alerts'!A13 -> ENDPOINT QUEUE FAILURES | C21: 300 | D21: ='Final_List-Alerts'!B13 -> Low | E21: source="/splunk/manhattan_active/ABQ/failure_count/message_failure_count_list.csv" host="misssplunksh01.corp.rndc-usa.com" index="ymc_dev_wms" sourcetype="msg_csv" NOT AU06CancelCartonDestinationEndpoint NOT EndpointId NOT AU06CancelCartonEndpoint NOT EX59_RouteStopDownload | rename Endpoint_Name as Name, Error_Count as Count | where Count > 100 | table Name Count | I21: 1 | J21: 1 | M21: 1 | P21: =MID(E21, LEN("source=""/splunk/manhattan_active/"), FIND("csv", E21) - LEN("source=""/splunk/manhattan_active/")+3) -> /ABQ/failure_count/message_failure_count_list.csv
A22: 1 | B22: ='Final_List-Alerts'!A16 -> ILPNS WITH NEGATIVE ALLOCATED QUANTITY API FAILURE | C22: 300 | D22: ='Final_List-Alerts'!B16 -> Low | E22: source="/splunk/manhattan_active/ABQ/lpn_negative_allocation/update_lpn_inv_check_status.csv" host="misssplunksh01.corp.rndc-usa.com" index="ymc_dev_wms" sourcetype="csv" "Update Lpn Inventory API Failed" | rename "Update Lpn Inventory API Status" as Status | table Status, _time | I22: 1 | J22: 1 | M22: 1 | P22: =MID(E22, LEN("source=""/splunk/manhattan_active/"), FIND("csv", E22) - LEN("source=""/splunk/manhattan_active/")+3) -> /ABQ/lpn_negative_allocation/update_lpn_inv_check_status.csv
A23: =A22+1 -> 2 | B23: ='Final_List-Alerts'!A23 -> LOCATION REBUILD FAILURE | C23: 300 | D23: ='Final_List-Alerts'!B23 -> Low | E23: source="/splunk/manhattan_active/ABQ/location_rebuild/location_rebuild_check_status.csv" host="misssplunksh01.corp.rndc-usa.com" index="ymc_dev_wms" "Location Rebuild API Failed" | rename "Location Rebuild API Status" as Status | table Status, _time | I23: 1 | J23: 1 | M23: 1 | P23: =MID(E23, LEN("source=""/splunk/manhattan_active/"), FIND("csv", E23) - LEN("source=""/splunk/manhattan_active/")+3) -> /ABQ/location_rebuild/location_rebuild_check_status.csv
A24: =A23+1 -> 3 | B24: ='Final_List-Alerts'!A29 -> OPEN PICK PACK TASK DETAILS API FAILURE | C24: 300 | D24: ='Final_List-Alerts'!B29 -> Low | E24: source="/splunk/manhattan_active/ABQ/tskdtls_comp_openpickpacktskdtls/open_pickpack_task_details_status.csv" host="misssplunksh01.corp.rndc-usa.com" index="ymc_dev_wms" sourcetype="csv" "Open Pick Pack Task Details API Failed" | rename "Open Pick Pack Task Details" as Status | table Status, _time | dedup Status | I24: 1 | J24: 1 | L24: 1 | M24: 1 | P24: =MID(E24, LEN("source=""/splunk/manhattan_active/"), FIND("csv", E24) - LEN("source=""/splunk/manhattan_active/")+3) -> /ABQ/tskdtls_comp_openpickpacktskdtls/open_pickpack_task_details_status.csv
A25: =A24+1 -> 4 | B25: ='Final_List-Alerts'!A31 -> OPEN TASK API FAILURE | C25: 300 | D25: ='Final_List-Alerts'!B31 -> Low | E25: source="/splunk/manhattan_active/ABQ/open_task/open_task_status.csv" host="misssplunksh01.corp.rndc-usa.com" index="ymc_dev_wms" sourcetype="csv" "Open Task API Failed" | rename "Open Task API Status" as Status, "Task Id" as TaskId | table TaskId, Status, _time | I25: 1 | J25: 1 | L25: 1 | M25: 1 | P25: =MID(E25, LEN("source=""/splunk/manhattan_active/"), FIND("csv", E25) - LEN("source=""/splunk/manhattan_active/")+3) -> /ABQ/open_task/open_task_status.csv
A26: =A25+1 -> 5 | B26: ='Final_List-Alerts'!A32 -> OPEN TASK DETAILS API FAILURE | C26: 300 | D26: ='Final_List-Alerts'!B32 -> Low | E26: source="/splunk/manhattan_active/ABQ/open_task_details/open_task_details_status.csv" host="misssplunksh01.corp.rndc-usa.com" index="ymc_dev_wms" sourcetype="csv" "Open Task Details API Failed" | rename "Open Task Details API Status" as Status | table Status, _time | I26: 1 | J26: 1 | L26: 1 | M26: 1 | P26: =MID(E26, LEN("source=""/splunk/manhattan_active/"), FIND("csv", E26) - LEN("source=""/splunk/manhattan_active/")+3) -> /ABQ/open_task_details/open_task_details_status.csv
A27: =A26+1 -> 6 | B27: ='Final_List-Alerts'!A56 -> USER TASK GROUP BULK IMPORT FAILURE | C27: 300 | D27: ='Final_List-Alerts'!B56 -> Low | E27: source="/splunk/manhattan_active/ABQ/user_task_group/user_task_group_status.csv" host="misssplunksh01.corp.rndc-usa.com" index="ymc_dev_wms" sourcetype="csv" "User Task Group Bulk Import API Failed" | rename "User Task Group Bulk Import API Status" as Status | table Status, _time | I27: 1 | J27: 1 | L27: 1 | M27: 1 | P27: =MID(E27, LEN("source=""/splunk/manhattan_active/"), FIND("csv", E27) - LEN("source=""/splunk/manhattan_active/")+3) -> /ABQ/user_task_group/user_task_group_status.csv
A28: =A27+1 -> 7 | B28: ='Final_List-Alerts'!A87 -> inventory_sync_schedule | C28: 1000 | D28: ='Final_List-Alerts'!B87 -> 0 | E28: source="/splunk/manhattan_active/ABQ/inventory_sync_schedule/inventory_sync_schedule_check_status.csv" host="misssplunksh01.corp.rndc-usa.com" index="ymc_dev_wms" "Inventory sync schedule API Failed" |rename "Inventory sync schedule API Status" as Status | table Status, _time | I28: 1 | J28: 1 | M28: 1 | P28: =MID(E28, LEN("source=""/splunk/manhattan_active/"), FIND("csv", E28) - LEN("source=""/splunk/manhattan_active/")+3) -> /ABQ/inventory_sync_schedule/inventory_sync_schedule_check_status.csv
A29: =A28+1 -> 8 | B29: ='Final_List-Alerts'!A85 -> mawm_consolidation_report | C29: 1000 | D29: ='Final_List-Alerts'!B85 -> 0 | O29: POR - MAWM - Shipped oLPN w/ Consolidation Location Assignment????
A30: =A29+1 -> 9 | B30: ='Final_List-Alerts'!A88 -> update_ext_display_barcode | C30: 1000 | D30: ='Final_List-Alerts'!B88 -> 0 | E30: | dbxquery query="select INVOICE, SHIP_TO, CUSTOMER_NUMBER, EMAIL, ITEM, PACK, ITEM_SIZE, SHIP_QTY, ORDER_QTY, ITEM_DESC from c_will_call_ark where tax_id is null" connection="CONF_OKL_WM13" | rename INVOICE AS Invoice, SHIP_TO AS "Ship To", CUSTOMER_NUMBER AS "Cust #" | eval ShortQty = ORDER_QTY - SHIP_QTY | fields - _raw, _time | stats list(ITEM) as "Item", list(ITEM_SIZE) as "Size", list(SHIP_QTY) AS "Ship Qty (Btls)", list(ORDER_QTY) AS "Ord Qty (Btls)", list(ShortQty) as "Short Qty (Btls)",list(PACK) AS "Pack" , list(ITEM_DESC) as "Item Description", values(EMAIL) as "Email" delim=":", by Invoice,"Ship To", "Cust #" | rex mode=sed field="Item Description" "s/:/\n/g" | rex mode=sed field="Ord Qty (Btls)" "s/:/\n/g" | rex mode=sed field=Size "s/:/\n/g" | rex mode=sed field="Ship Qty (Btls)" "s/:/\n/g" | rex mode=sed field="Short Qty (Btls)" "s/:/\n/g" | rex mode=sed field="Pack" "s/:/\n/g" | rex mode=sed field="Item" "s/:/\n/g" | rex mode=sed field="Item Description" "s/ /_/g" | eval "Ship To"=lower('Ship To') | eval "Ship To"=upper(substr('Ship To',1,1)).substr('Ship To',2) |table Invoice "Ship To" "Cust #" Email Item Pack Size "Ship Qty (Btls)" "Ord Qty (Btls)" "Short Qty (Btls)" "Item Description" | J30: 1 | K30: 1 | L30: 1 | M30: 1
B31: Divert Confirm Endpoint Shutdown
B32: WMS - Divert Confirm Endpoint Shutdown
B43: =B2 -> Tasks | C43: =P2 -> csv file name
B44: =B5 -> ATL In Transit RMA ASNs > 30 Days Splunk Alert | C44: =P5 -> /ALLMAWM/hawaii-in-transit-rma-asns/Logs/hawaii-in-transit-rma-asns-HAW.csv | F44: Kinsy : Need to lookinto this
B45: =B6 -> INVENTORY SYNC SCHEDULE API FAILED | C45: =P6 -> /ABQ/inventory_sync_schedule/inventory_sync_schedule_check_status.csv | F45: Combine two schedules
B46: =B9 -> ITEM IMAGE URL FAILURE | C46: =P9 -> /ABQ/item_image_url/itemURL_bulk_import_check_status.csv | F46: /splunk/FTP/DWH/Product_image_dimension.txt
B47: =B10 -> DIVERT CONFIRMATION DOWN | C47: =P10 -> /ALLMAWM/au02_divert_confirm_source_destination_down/au02_divert_confirm_source_destination_down_Prod.csv
B48: =B11 -> PICK LOCATIONS WITH NEGATIVE TBF API FAILURE | C48: =P11 -> /ABQ/pick_loc_negative_tbf/pick_loc_negative_tbf_status.csv
B49: =B12 -> PICK LOCATIONS WITH TBF QUANTITY AND NO OPEN TASK DETAILS API FAILURE | C49: =P12 -> /ABQ/pick_loc_tbf_qty_taskdtls/pick_loc_tbf_qty_taskdtls_status.csv
B50: =B13 -> SLOTTING ITEM DEMAND PACK FAILURE | C50: =P13 -> /ABQ/slot_itemdemand_pack/slotitemdemand_pack_check_status.csv
B51: =B14 -> SLOTTING ITEM DEMAND UNIT FAILURE | C51: =P14 -> /ABQ/slot_itemdemand_unit/slotitemdemand_unit_check_status.csv
...

Sheet Combination Splunk Activities
A1: Script Details | L1: House Enabled
A2: Current Script Name | B2: In Use | C2: New Script Name | D2: Description | E2: Desired Cron Frequency | F2: Script Type | G2: Email Notification | H2: Tool | I2: Priority | J2: Note | K2: Unstarted Work/In Design/Being Develped/Deployed | L2: ABQ | M2: ARK | N2: ASH | O2: ATL | P2: AUB | Q2: CCR | R2: CHI | S2: COL | T2: DEN | U2: DFB | V2: ELP | W2: FAR | X2: GRP | Y2: HAW | Z2: HOU | AA2: IND | AB2: JAC | AC2: JES | AD2: KAP | AE2: KAU | AF2: LAF | AG2: LIV | AH2: LOU | AI2: LUB | AJ2: MAU | AK2: NEW | AL2: OAH | AM2: OKL | AN2: OMA | AO2: ORL | AP2: PEN | AQ2: PHO | AR2: POR | AS2: ROM | AT2: RVR | AU2: SAA | AV2: SIO | AW2: TAM | AX2: TOL | AY2: WSD
A3: alloclpns_noopntskdtls | B3: No | D3: Automated cleanup script | E3: Disabled | J3: CRON Disabled for all sites | L3: No | M3: No | N3: No | O3: No | P3: No | Q3: No | R3: No | S3: No | T3: No | U3: No | V3: No | W3: No | X3: No | Y3: No | Z3: No | AA3: No | AB3: No | AC3: No | AD3: No | AE3: No | AF3: No | AG3: No | AH3: No | AI3: No | AJ3: No | AK3: No | AL3: No | AM3: No | AN3: No | AO3: No | AP3: No | AQ3: No | AR3: No | AS3: No | AT3: No | AU3: No | AV3: No | AW3: No | AX3: No | AY3: No
A4: asn_parameter_missing | B4: Yes | C4: ASN Receiving Template Header Application Parameter Missing | D4: This parameter helps to avoid child loads during ASN updates. This reduces component memory usage, DB queries, and improves GC stability. | E4: 8:14 on Monday- Prod | F4: API, Python | G4: Y | H4: Application Parameter Tools | J4: MAWM Scheduled Script Dashboard for API's | K4: Deployed | L4: Yes | M4: Yes | N4: Yes | O4: Yes | P4: Yes | Q4: Yes | R4: Yes | S4: Yes | T4: Yes | U4: Yes | V4: Yes | W4: Yes | X4: Yes | Y4: No | Z4: Yes | AA4: Yes | AB4: Yes | AC4: Yes | AD4: No | AE4: No | AF4: Yes | AG4: Yes | AH4: Yes | AI4: Yes | AJ4: No | AK4: No | AL4: No | AM4: Yes | AN4: Yes | AO4: Yes | AP4: Yes | AQ4: No | AR4: Yes | AS4: No | AT4: Yes | AU4: Yes | AV4: Yes | AW4: Yes | AX4: No | AY4: Yes
A5: asn_parameter_missing | B5: Yes | C5: ASN Receiving Template Header Application Parameter Missing | D5: This parameter helps to avoid child loads during ASN updates. This reduces component memory usage, DB queries, and improves GC stability. | E5: 8:16 on Monday- Stage | F5: API, Python | G5: N | H5: Application Parameter Tools | K5: Deployed | L5: Yes | M5: Yes | N5: Yes | O5: Yes | P5: Yes | Q5: Yes | R5: Yes | S5: Yes | T5: Yes | U5: Yes | V5: Yes | W5: Yes | X5: Yes | Y5: No | Z5: Yes | AA5: Yes | AB5: Yes | AC5: Yes | AD5: No | AE5: No | AF5: Yes | AG5: Yes | AH5: Yes | AI5: Yes | AJ5: No | AK5: No | AL5: No | AM5: Yes | AN5: Yes | AO5: Yes | AP5: Yes | AQ5: No | AR5: Yes | AS5: No | AT5: Yes | AU5: Yes | AV5: Yes | AW5: Yes | AX5: No | AY5: Yes
A6: component_health_check | B6: No | D6: No longer Applicable | E6: Disabled | J6: Only available for LAF, CRON disabled | L6: No | M6: No | N6: No | O6: No | P6: No | Q6: No | R6: No | S6: No | T6: No | U6: No | V6: No | W6: No | X6: No | Y6: No | Z6: No | AA6: No | AB6: No | AC6: No | AD6: No | AE6: No | AF6: No | AG6: No | AH6: No | AI6: No | AJ6: No | AK6: No | AL6: No | AM6: No | AN6: No | AO6: No | AP6: No | AQ6: No | AR6: No | AS6: No | AT6: No | AU6: No | AV6: No | AW6: No | AX6: No | AY6: No
A7: dcorder_ops_parameter_missing | B7: Yes | C7: Dcorder OPS Application Parameter Missing | D7: Max Cut off hours to monitor order planning run metrics | E7: 8:12 on Monday- Prod | F7: API | G7: N | H7: Application Parameter Tools | J7: MAWM Scheduled Script Dashboard for API's----Brandon Johnson | K7: Deployed | L7: Yes | M7: Yes | N7: Yes | O7: Yes | P7: Yes | Q7: Yes | R7: Yes | S7: Yes | T7: Yes | U7: Yes | V7: Yes | W7: Yes | X7: Yes | Y7: No | Z7: Yes | AA7: Yes | AB7: Yes | AC7: Yes | AD7: No | AE7: No | AF7: Yes | AG7: Yes | AH7: Yes | AI7: Yes | AJ7: No | AK7: No | AL7: No | AM7: Yes | AN7: Yes | AO7: Yes | AP7: Yes | AQ7: No | AR7: Yes | AS7: No | AT7: Yes | AU7: Yes | AV7: Yes | AW7: Yes | AX7: No | AY7: Yes
A8: dcorder_ops_parameter_missing | B8: Yes | C8: Dcorder OPS Application Parameter Missing | D8: Max Cut off hours to monitor order planning run metrics | E8: 8:10 on Monday- Stage | F8: API | G8: N | H8: Application Parameter Tools | K8: Deployed | L8: Yes | M8: Yes | N8: Yes | O8: Yes | P8: Yes | Q8: Yes | R8: Yes | S8: Yes | T8: Yes | U8: Yes | V8: Yes | W8: Yes | X8: Yes | Y8: No | Z8: Yes | AA8: Yes | AB8: Yes | AC8: Yes | AD8: No | AE8: No | AF8: Yes | AG8: Yes | AH8: Yes | AI8: Yes | AJ8: No | AK8: No | AL8: No | AM8: Yes | AN8: Yes | AO8: Yes | AP8: Yes | AQ8: No | AR8: Yes | AS8: No | AT8: Yes | AU8: Yes | AV8: Yes | AW8: Yes | AX8: No | AY8: Yes
A9: dybd_parameter | B9: Yes | C9: DYBD Putaway Application Parameter Not Set | D9: Aids in the putaway portion of DYBD Replenishment to prevent the LPN expected container promps during fill portion of task | E9: 9:30 on Monday- Prod | F9: API, Python | G9: N | H9: Application Parameter Tools | J9: POST {{app_host}}/putaway/api/idempotency/applicationParameter/search { "Query": "ApplicationParameterId != null", "Size": 1 } Trigger Condition: Fire the alert if no PK value is returned for the Org in question. | K9: Deployed | L9: Yes | M9: Yes | N9: Yes | O9: Yes | P9: Yes | Q9: Yes | R9: Yes | S9: Yes | T9: Yes | U9: Yes | V9: Yes | W9: Yes | X9: Yes | Y9: No | Z9: Yes | AA9: Yes | AB9: Yes | AC9: Yes | AD9: No | AE9: No | AF9: Yes | AG9: Yes | AH9: Yes | AI9: Yes | AJ9: No | AK9: No | AL9: No | AM9: Yes | AN9: Yes | AO9: Yes | AP9: Yes | AQ9: No | AR9: Yes | AS9: No | AT9: Yes | AU9: Yes | AV9: Yes | AW9: Yes | AX9: No | AY9: Yes
A10: dybd_parameter | B10: Yes | C10: DYBD Putaway Application Parameter Not Set | D10: Aids in the putaway portion of DYBD Replenishment to prevent the LPN expected container promps during fill portion of task | E10: 9:45 on Monday- Stage | F10: API, Python | G10: N | H10: Application Parameter Tools | K10: Deployed | L10: Yes | M10: Yes | N10: Yes | O10: Yes | P10: Yes | Q10: Yes | R10: Yes | S10: Yes | T10: Yes | U10: Yes | V10: Yes | W10: Yes | X10: Yes | Y10: No | Z10: Yes | AA10: Yes | AB10: Yes | AC10: Yes | AD10: No | AE10: No | AF10: Yes | AG10: Yes | AH10: Yes | AI10: Yes | AJ10: No | AK10: No | AL10: No | AM10: Yes | AN10: Yes | AO10: Yes | AP10: Yes | AQ10: No | AR10: Yes | AS10: No | AT10: Yes | AU10: Yes | AV10: Yes | AW10: Yes | AX10: No | AY10: Yes
A11: missing_TGE_parameter | B11: Yes | C11: Missing Putaway Replenishment TGE Application Parameter | D11: Allows to bypass TGE checks on putaway portion of replen tasks | E11: 8:00 on Monday | F11: API, Python | G11: Y | H11: Application Parameter Tools | J11: Under MAWM Scheduled Script Dashboard for API's | K11: Deployed | L11: Yes | M11: Yes | N11: Yes | O11: Yes | P11: Yes | Q11: Yes | R11: Yes | S11: Yes | T11: Yes | U11: Yes | V11: Yes | W11: Yes | X11: Yes | Y11: No | Z11: Yes | AA11: Yes | AB11: Yes | AC11: Yes | AD11: No | AE11: No | AF11: Yes | AG11: Yes | AH11: Yes | AI11: Yes | AJ11: No | AK11: No | AL11: No | AM11: Yes | AN11: Yes | AO11: Yes | AP11: Yes | AQ11: No | AR11: Yes | AS11: No | AT11: Yes | AU11: Yes | AV11: Yes | AW11: Yes | AX11: No | AY11: Yes
A12: dynamic_casepick_liquor | B12: Yes | C12: Mark Dynamic Case Pick | D12: LIV Heavy Hitters | E12: 00:00 every day Mon-Sat | F12: API, Python | G12: Y | H12: MAWM Scheduled Script Dashboard for API's | I12: 5 | J12: Only for LIV, Related to line 62 & 63 on the Final List. | K12: Being Developed | L12: No | M12: No | N12: No | O12: No | P12: No | Q12: No | R12: No | S12: No | T12: No | U12: No | V12: No | W12: No | X12: No | Y12: No | Z12: No | AA12: No | AB12: No | AC12: No | AD12: No | AE12: No | AF12: No | AG12: Yes | AH12: No | AI12: No | AJ12: No | AK12: No | AL12: No | AM12: No | AN12: No | AO12: No | AP12: No | AQ12: No | AR12: No | AS12: No | AT12: No | AU12: No | AV12: No | AW12: No | AX12: No | AY12: No
A13: dynamic_casepick_wine | B13: Yes | C13: Mark Dynamic Wine | D13: LIV Heavy Hitters | E13: 19:00 every day Mon through Fri | F13: API, Python | G13: Y | H13: MAWM Scheduled Script Dashboard for API's | I13: 4 | J13: Only for LIV, Related to line 62 & 63 on the Final List. | K13: Being Developed | L13: No | M13: No | N13: No | O13: No | P13: No | Q13: No | R13: No | S13: No | T13: No | U13: No | V13: No | W13: No | X13: No | Y13: No | Z13: No | AA13: No | AB13: No | AC13: No | AD13: No | AE13: No | AF13: No | AG13: Yes | AH13: No | AI13: No | AJ13: No | AK13: No | AL13: No | AM13: No | AN13: No | AO13: No | AP13: No | AQ13: No | AR13: No | AS13: No | AT13: No | AU13: No | AV13: No | AW13: No | AX13: No | AY13: No
A14: dynamic_casepick_wine | B14: Yes | C14: Mark Dynamic Wine | D14: LIV Heavy Hitters | E14: At minute 0, 15, 30, and 45 past hour 17 and 18 on every day-of-week from Monday through Friday | F14: API, Python | G14: Y | H14: MAWM Scheduled Script Dashboard for API's | I14: 4 | J14: Only for LIV, Related to line 62 & 63 on the Final List. | K14: Being Developed | L14: No | M14: No | N14: No | O14: No | P14: No | Q14: No | R14: No | S14: No | T14: No | U14: No | V14: No | W14: No | X14: No | Y14: No | Z14: No | AA14: No | AB14: No | AC14: No | AD14: No | AE14: No | AF14: No | AG14: Yes | AH14: No | AI14: No | AJ14: No | AK14: No | AL14: No | AM14: No | AN14: No | AO14: No | AP14: No | AQ14: No | AR14: No | AS14: No | AT14: No | AU14: No | AV14: No | AW14: No | AX14: No | AY14: No
A15: will_call_master | B15: Yes | C15: Will Call Master | D15: Notifies SalesPerson when Will Call order is completed | E15: See CRON Frequency Tab | F15: DB Query / API Import / Python | G15: Y | H15: New BI Tool/ Lambda Function | K15: Being Developed | L15: Yes | M15: Yes | N15: Yes | O15: Yes | P15: No | Q15: Yes | R15: No | S15: Yes | T15: Yes | U15: Yes | V15: Yes | W15: Yes | X15: Yes | Y15: No | Z15: Yes | AA15: Yes | AB15: Yes | AC15: Yes | AD15: No | AE15: No | AF15: Yes | AG15: Yes | AH15: Yes | AI15: Yes | AJ15: No | AK15: No | AL15: No | AM15: Yes | AN15: Yes | AO15: Yes | AP15: Yes | AQ15: No | AR15: No | AS15: No | AT15: No | AU15: Yes | AV15: Yes | AW15: Yes | AX15: No | AY15: Yes
A16: endpoint_status | B16: Yes | C16: Endpoint Status | D16: Queries status of AU* Endpoints | E16: At Minute 15 | F16: API , Python | G16: Y | H16: Alert | L16: Yes | M16: Yes | N16: Yes | O16: Yes | P16: Yes | Q16: Yes | R16: Yes | S16: Yes | T16: Yes | U16: Yes | V16: Yes | W16: Yes | X16: Yes | Y16: No | Z16: Yes | AA16: Yes | AB16: Yes | AC16: Yes | AD16: No | AE16: No | AF16: Yes | AG16: Yes | AH16: Yes | AI16: Yes | AJ16: No | AK16: No | AL16: No | AM16: Yes | AN16: Yes | AO16: Yes | AP16: Yes | AQ16: No | AR16: Yes | AS16: No | AT16: Yes | AU16: Yes | AV16: Yes | AW16: Yes | AX16: No | AY16: Yes
A17: inventory_sync_all | B17: No | D17: Fires weekly inventory Sync | E17: Disabled | F17: API Job | G17: Y | H17: MAWM Scheduled Script Dashboard for API's | J17: CRON Disabled for all sites | L17: No | M17: No | N17: No | O17: No | P17: No | Q17: No | R17: No | S17: No | T17: No | U17: No | V17: No | W17: No | X17: No | Y17: No | Z17: No | AA17: No | AB17: No | AC17: No | AD17: No | AE17: No | AF17: No | AG17: No | AH17: No | AI17: No | AJ17: No | AK17: No | AL17: No | AM17: No | AN17: No | AO17: No | AP17: No | AQ17: No | AR17: No | AS17: No | AT17: No | AU17: No | AV17: No | AW17: No | AX17: No | AY17: No
A18: inventory_sync_schedule | B18: Yes | C18: WMS Inventory Sync | D18: Triggers Inventory Sync for ERPs | E18: See CRON Frequency Tab | G18: N | H18: MAWM Scheduled Script Dashboard for API's | I18: 1 | J18: Line 87 | K18: Being Developed | L18: Yes | M18: Yes | N18: Yes | O18: Yes | P18: Yes | Q18: Yes | R18: Yes | S18: Yes | T18: Yes | U18: Yes | V18: Yes | W18: Yes | X18: Yes | Y18: No | Z18: Yes | AA18: Yes | AB18: Yes | AC18: Yes | AD18: No | AE18: No | AF18: Yes | AG18: Yes | AH18: Yes | AI18: Yes | AJ18: No | AK18: No | AL18: No | AM18: Yes | AN18: Yes | AO18: Yes | AP18: Yes | AQ18: No | AR18: Yes | AS18: No | AT18: Yes | AU18: Yes | AV18: Yes | AW18: Yes | AX18: No | AY18: Yes
A19: item_bulk_import | B19: Yes | C19: Item Oddball SKU Update | D19: Marks SKUs as oddball | E19: See CRON Frequency Tab | F19: SQL, API | G19: N | H19: MAWM Scheduled Script Dashboard for API's | I19: Complete | J19: Pending Production Release | K19: Being Developed | L19: Yes | M19: Yes | N19: Yes | O19: Yes | P19: Yes | Q19: Yes | R19: Yes | S19: Yes | T19: Yes | U19: Yes | V19: Yes | W19: Yes | X19: Yes | Y19: No | Z19: Yes | AA19: Yes | AB19: Yes | AC19: Yes | AD19: No | AE19: No | AF19: Yes | AG19: Yes | AH19: Yes | AI19: Yes | AJ19: No | AK19: No | AL19: No | AM19: Yes | AN19: Yes | AO19: Yes | AP19: Yes | AQ19: No | AR19: Yes | AS19: No | AT19: Yes | AU19: Yes | AV19: Yes | AW19: Yes | AX19: No | AY19: Yes
A20: item_image_url | B20: Yes | C20: Item Image URL Import | D20: Imports Item Image URLs from data warehouse feed into WM | E20: See CRON Frequency Tab | F20: Python, API | G20: N | H20: MAWM Scheduled Script Dashboard for API's | I20: 3 | J20: Line 19 | K20: Being Developed | L20: Yes | M20: Yes | N20: Yes | O20: Yes | P20: Yes | Q20: Yes | R20: Yes | S20: Yes | T20: Yes | U20: Yes | V20: Yes | W20: Yes | X20: Yes | Y20: No | Z20: Yes | AA20: Yes | AB20: Yes | AC20: Yes | AD20: No | AE20: No | AF20: Yes | AG20: Yes | AH20: Yes | AI20: Yes | AJ20: No | AK20: No | AL20: No | AM20: Yes | AN20: Yes | AO20: Yes | AP20: Yes | AQ20: No | AR20: Yes | AS20: No | AT20: Yes | AU20: Yes | AV20: Yes | AW20: Yes | AX20: No | AY20: Yes
A21: item_master_search | B21: Yes | C21: Item Master Left Join Search Application Parameter | D21: The application parameter within the item master component is necessary to prevent cubing errors resulting in orders from deselecting and ensuring Item Level verification PIX from receiving populate with the correct data. | E21: 7:45 on Monday | F21: Python, API | G21: N | H21: Application Parameter Tools | J21: POST {{app_host}}/item-master/api/idempotency/applicationParameter/search { "Query": "ApplicationParameterId = item.remove.left.join.item.search and Value = true" } | K21: Deployed | L21: Yes | M21: Yes | N21: Yes | O21: Yes | P21: Yes | Q21: Yes | R21: Yes | S21: Yes | T21: Yes | U21: Yes | V21: Yes | W21: Yes | X21: Yes | Y21: No | Z21: Yes | AA21: Yes | AB21: Yes | AC21: Yes | AD21: No | AE21: No | AF21: Yes | AG21: Yes | AH21: Yes | AI21: Yes | AJ21: No | AK21: No | AL21: No | AM21: Yes | AN21: Yes | AO21: Yes | AP21: Yes | AQ21: No | AR21: Yes | AS21: No | AT21: Yes | AU21: Yes | AV21: Yes | AW21: Yes | AX21: No | AY21: Yes
A22: item_volume | B22: Yes | E22: 8:00 on Sunday | J22: Reach out to Shiva or Kinsy or Thomas for details | L22: Yes | M22: Yes | N22: Yes | O22: Yes | P22: Yes | Q22: Yes | R22: Yes | S22: Yes | T22: Yes | U22: Yes | V22: Yes | W22: Yes | X22: Yes | Y22: No | Z22: Yes | AA22: Yes | AB22: Yes | AC22: Yes | AD22: No | AE22: No | AF22: Yes | AG22: Yes | AH22: Yes | AI22: Yes | AJ22: No | AK22: No | AL22: No | AM22: Yes | AN22: Yes | AO22: Yes | AP22: Yes | AQ22: No | AR22: Yes | AS22: No | AT22: Yes | AU22: Yes | AV22: Yes | AW22: Yes | AX22: No | AY22: Yes
A23: ITEMLOC_PRD | B23: Yes | C23: ItemLoc PRD | D23: Item locations are sent into staging tables that are read by ERPs | E23: See CRON Frequency Tab | F23: SQL, Python | G23: N | H23: MAWM Scheduled Script Dashboard for API's | I23: 2 | J23: Line 61 | K23: Being Developed | L23: Yes | M23: Yes | N23: Yes | O23: Yes | P23: No | Q23: Yes | R23: No | S23: Yes | T23: Yes | U23: Yes | V23: Yes | W23: Yes | X23: Yes | Y23: No | Z23: Yes | AA23: Yes | AB23: Yes | AC23: Yes | AD23: No | AE23: No | AF23: Yes | AG23: Yes | AH23: Yes | AI23: Yes | AJ23: No | AK23: No | AL23: No | AM23: Yes | AN23: Yes | AO23: Yes | AP23: Yes | AQ23: No | AR23: No | AS23: No | AT23: No | AU23: Yes | AV23: Yes | AW23: Yes | AX23: No | AY23: Yes
A24: location_rebuild | B24: No | C24: Location Rebuild | D24: Rebuilding Locations in WM | E24: Disabled | F24: API | J24: CRON Disabled for all sites | L24: No | M24: No | N24: No | O24: No | P24: No | Q24: No | R24: No | S24: No | T24: No | U24: No | V24: No | W24: No | X24: No | Y24: No | Z24: No | AA24: No | AB24: No | AC24: No | AD24: No | AE24: No | AF24: No | AG24: No | AH24: No | AI24: No | AJ24: No | AK24: No | AL24: No | AM24: No | AN24: No | AO24: No | AP24: No | AQ24: No | AR24: No | AS24: No | AT24: No | AU24: No | AV24: No | AW24: No | AX24: No | AY24: No
A25: lpn_consumed_cancel_allocation | B25: No | D25: No longer Applicable | E25: Disabled | J25: CRON Disabled for all sites | L25: Yes | M25: No | N25: Yes | O25: Yes | P25: No | Q25: Yes | R25: No | S25: Yes | T25: Yes | U25: Yes | V25: Yes | W25: Yes | X25: Yes | Y25: No | Z25: Yes | AA25: Yes | AB25: Yes | AC25: Yes | AD25: No | AE25: No | AF25: Yes | AG25: Yes | AH25: Yes | AI25: Yes | AJ25: No | AK25: No | AL25: No | AM25: Yes | AN25: Yes | AO25: Yes | AP25: Yes | AQ25: No | AR25: Yes | AS25: No | AT25: No | AU25: Yes | AV25: Yes | AW25: Yes | AX25: No | AY25: Yes
A26: lpn_location_assignment | B26: No | C26: LPN Location Assignment | D26: Tracks invalid location assignments via API delete failures | E26: 5* | F26: Python, API, SQL | G26: Y | L26: No | M26: No | N26: No | O26: No | P26: No | Q26: No | R26: No | S26: No | T26: No | U26: No | V26: No | W26: No | X26: Yes | Y26: No | Z26: No | AA26: No | AB26: No | AC26: No | AD26: No | AE26: No | AF26: No | AG26: No | AH26: No | AI26: No | AJ26: No | AK26: No | AL26: No | AM26: No | AN26: No | AO26: No | AP26: No | AQ26: No | AR26: No | AS26: No | AT26: No | AU26: No | AV26: No | AW26: No | AX26: No | AY26: No
A27: lpn_negative_allocation | B27: No | D27: No longer Applicable | E27: Disabled | J27: CRON Disabled for all sites | L27: Yes | M27: No | N27: Yes | O27: Yes | P27: No | Q27: Yes | R27: No | S27: Yes | T27: Yes | U27: Yes | V27: Yes | W27: Yes | X27: Yes | Y27: No | Z27: Yes | AA27: Yes | AB27: Yes | AC27: Yes | AD27: No | AE27: No | AF27: Yes | AG27: Yes | AH27: Yes | AI27: Yes | AJ27: No | AK27: No | AL27: No | AM27: Yes | AN27: Yes | AO27: Yes | AP27: Yes | AQ27: No | AR27: Yes | AS27: No | AT27: No | AU27: Yes | AV27: Yes | AW27: Yes | AX27: No | AY27: Yes
